Workbook

Sheet 1.설계입력
B2: 사이클로이드 감속기 설계 입력
B3: 노란 셀만 입력하세요. 회색 셀은 자동 계산됩니다.
B5: 기본 설계 파라미터 (논문 A Fig.3)
B6: 핀 중심원 반경 | C6: 82 | D6: mm | E6: 핀들의 중심이 놓인 원의 반경. 감속기 외형 크기를 결정 | G6: r_p
B7: 핀 반경 | C7: 4 | D7: mm | E7: 핀 하나의 반경. 논문 A의 등거리(equidistant) q | G7: r_rp
B8: 편심량 | C8: 1.5 | D8: mm | E8: 입력축 편심. 꽃잎 깊이 = 2a | G8: a
B9: 사이클로이드 이빨 수 | C9: 39 | D9: 개 | E9: 감속비와 동일. 이 값이 곧 1단 감속비 | G9: z_c
B10: 기어 폭 | C10: 15 | D10: mm | E10: 축방향 두께. 접촉 길이로 쓰임 | G10: b_c
B11: 이빨당 계산 점 수 | C11: 95 | D11: 개 | E11: 논문 A 기본값 95. 이빨 하나 윤곽의 해상도 | G11: k
B12: 전체윤곽 각 스텝 | C12: 0.2 | D12: deg | E12: 작을수록 정밀. 0.2도면 1800점 (논문 A 값) | G12: dphi_out
B14: 유도 파라미터 (논문 A Fig.4 / 자동 계산)
B15: 핀 개수 | C15: =$C$9+1 -> 40 | D15: 개 | E15: z_p = z_c + 1 <- 이빨은 항상 핀보다 1개 적다 | G15: z_p
B16: 단폭 계수 | C16: =$C$8*$C$15/$C$6 -> 0.73170732 | D16: - | E16: K1 = a*z_p/r_p 형상 무차원수. 권장 0.5~0.9 | G16: K_1
B17: 상대 전달비 | C17: =$C$15/$C$9 -> 1.025641 | D17: - | E17: i_H = z_p/z_c 논문 B 수식에 쓰임 | G17: i_H
B18: 감속비 | C18: =$C$9 -> 39 | D18: : 1 | E18: z_c 와 같음. 크랭크축 z_c회전 -> 출력 1회전 | G18: i
B19: Q (논문 A) | C19: =$C$8*$C$15 -> 60 | D19: mm | E19: Q = a*z_p 논문 A Shin&Kwon 계수 | G19: Q
B20: 이빨하나 각 스텝 | C20: =360/($C$9*$C$11) -> 0.097165992 | D20: deg | E20: dphi = 360/(z_c*k) 논문 A: 0.344498 | G20: dphi_lobe
B22: 설계 조건 검증 (통과해야 제작 가능)
B23: 구동 성립 조건 | C23: =$C$6/($C$8*$C$15) -> 1.3666667 | D23: =IF($C$6/($C$8*$C$15)>1,"통과","위반: 편심 a를 줄이거나 r_p를 키우세요") -> 통과 | E23: r_p/(a*z_p) > 1 이것이 깨지면 치형이 자기교차하여 형상 자체가 성립하지 않음
B24: 단폭계수 범위 | C24: =$C$16 -> 0.73170732 | D24: =IF(AND($C$16>=0.5,$C$16<=0.9),"통과",IF($C$16>=1,"위반: K1>=1 은 형상 불성립","주의: 권장 0.5~0.9 벗어남")) -> 통과 | E24: K1 = a*z_p/r_p. 1 이상이면 불성립, 너무 작으면 이빨이 얕아 감속효율 저하
B25: 오프셋 성립 | C25: =$C$7 -> 4 | D25: =IF($C$7<$C$8*$C$15/2,"통과","주의: 핀반경이 큼. 이빨끝 곡률 확인 필요") -> 통과 | E25: 핀 반경이 치형 최소 곡률반경보다 크면 등거리 곡선이 파괴됨
B26: 이빨 끝 반경 | C26: =$C$6-$C$7+$C$8 -> 79.5 | D26: 참고값 | E26: r_p - r_rp + a 치형 최대 반경 (계산 검산용)
B27: 이빨 골 반경 | C27: =$C$6-$C$7-$C$8 -> 76.5 | D27: 참고값 | E27: r_p - r_rp - a 치형 최소 반경. 꽃잎 깊이는 2a
B30: 치형 수정 계수 (논문 B / 실제 제작에 필수)
B31: 표준 치형은 틈새가 0이므로 조립·윤활·오차보상이 불가합니다. 반드시 수정해야 합니다.
B32: 반경 틈새 총량 | C32: 0.005 | D32: mm | E32: 조립·윤활 요구가 정하는 값. 논문 B는 0.005mm 사용 | G32: dr
B33: 핀위치 수정 | C33: -0.0031 | D33: mm | E33: 음수여야 함. 이빨 끝·뿌리에 틈 생성. 논문 B Case a 값 | G33: d_rp
B34: 핀반경 수정 | C34: 0.0081 | D34: mm | E34: 양수여야 함. 이빨 측면에 틈 생성. 논문 B Case a 값 | G34: d_rrp
B35: 경험식 권장값 (참고)
B36: d_rrp (경험식) | C36: =IF($C$16>=1,"K1>=1 이므로 계산 불가",$C$32/(1-SQRT(MAX(0,1-$C$16^2)))) -> 0.015704453 | E36: 논문 B 식(18). Song 예제에서 0.0157
B37: d_rp (경험식) | C37: =IF($C$16>=1,"K1>=1 이므로 계산 불가",-$C$32*SQRT(MAX(0,1-$C$16^2))/(1-SQRT(MAX(0,1-$C$16^2)))) -> -0.010704453 | E37: 논문 B 식(19). Song 예제에서 -0.0107
B38: 수정계수 합 검증 | C38: =$C$33+$C$34 -> 0.005 | D38: =IF(ABS($C$33+$C$34-$C$32)<0.0000001,"통과","불일치: 합이 dr과 달라요") -> 통과 | E38: d_rp + d_rrp = dr 이어야 함. 논문 B Case b는 이 제약을 위반(0.0059)
B39: 수정 후 K1 | C39: =$C$8*$C$15/($C$6+$C$33) -> 0.73173498 | E39: 핀위치 수정 시 K1 갱신 필수 (논문 B 명시). 이 값이 수정치형 계산에 쓰임
B41: 성능 계산용 입력 (파이썬 solver 가 읽습니다)
B42: 출력 토크 T | C42: 420 | D42: N.m | E42: 출력축 토크. 논문 B 예제는 420 N.m. 접촉력 계산에 쓰입니다
E43: 전달오차·백래시·접촉력은 수식으로 불가능하므로 solver 폴더의 성능계산.bat 을 실행하면 [6.성능계산] 시트가 생깁니다.

Sheet 2.치형좌표
A1: 치형 좌표 계산 (논문 A 식1·2 / 수정 치형 / 논문 B 식20)
A2: =IF('1.설계입력'!$C$6/('1.설계입력'!$C$8*'1.설계입력'!$C$15)>1,"phi 0~360도 전체 윤곽입니다. 표준 치형과 수정 치형을 나란히 냅니다.","경고: 구동 조건 위반. [1.설계입력] 을 먼저 고치세요. 아래 좌표는 물리적으로 무효입니다.") -> phi 0~360도 전체 윤곽입니다. 표준 치형과 수정 치형을 나란히 냅니다.
A4: phi [deg] | B4: phi [rad] | C4: Psi 표준 | D4: Bx 표준 | E4: By 표준 | F4: Psi 수정 | G4: x 수정 | H4: y 수정 | I4: 반경 표준 | J4: 반경 수정 | K4: 틈새 [mm] | M4: 요약 (검산용)
A5: 논문A | B5: RADIANS | C5: 식(2) ATAN2 | D5: 식(1) | E5: 식(1) | F5: 식(2) 수정값 | G5: 식(1) 수정값 | H5: 식(1) 수정값 | I5: sqrt | J5: sqrt | K5: 논문B 식(20) 0~180도만 | M5: 표준 최대 반경 | N5: =MAX(I6:I1805) -> 79.5 | O5: 이론값 r_p - r_rp + a 와 같아야 함
A6: =0 -> 0 | B6: =RADIANS(A6) -> 0 | C6: =ATAN2('1.설계입력'!$C$6/('1.설계입력'!$C$8*'1.설계입력'!$C$15)-COS((1-'1.설계입력'!$C$15)*B6),SIN((1-'1.설계입력'!$C$15)*B6)) -> 0 | D6: ='1.설계입력'!$C$6*COS(B6)-'1.설계입력'!$C$7*COS(B6+C6)-'1.설계입력'!$C$8*COS('1.설계입력'!$C$15*B6) -> 76.5 | E6: =-'1.설계입력'!$C$6*SIN(B6)+'1.설계입력'!$C$7*SIN(B6+C6)+'1.설계입력'!$C$8*SIN('1.설계입력'!$C$15*B6) -> 0 | F6: =ATAN2(('1.설계입력'!$C$6+'1.설계입력'!$C$33)/('1.설계입력'!$C$8*'1.설계입력'!$C$15)-COS((1-'1.설계입력'!$C$15)*B6),SIN((1-'1.설계입력'!$C$15)*B6)) -> 0 | G6: =('1.설계입력'!$C$6+'1.설계입력'!$C$33)*COS(B6)-('1.설계입력'!$C$7+'1.설계입력'!$C$34)*COS(B6+F6)-'1.설계입력'!$C$8*COS('1.설계입력'!$C$15*B6) -> 76.4888 | H6: =-('1.설계입력'!$C$6+'1.설계입력'!$C$33)*SIN(B6)+('1.설계입력'!$C$7+'1.설계입력'!$C$34)*SIN(B6+F6)+'1.설계입력'!$C$8*SIN('1.설계입력'!$C$15*B6) -> 0 | I6: =SQRT(D6^2+E6^2) -> 76.5 | J6: =SQRT(G6^2+H6^2) -> 76.4888 | K6: =IF(OR(A6>180,'1.설계입력'!$C$39>=1),"",'1.설계입력'!$C$34*(1-SIN(B6)/SQRT(1+'1.설계입력'!$C$39^2-2*'1.설계입력'!$C$39*COS(B6)))-'1.설계입력'!$C$33*(1-'1.설계입력'!$C$39*COS(B6)-SQRT(MAX(0,1-'1.설계입력'!$C$39^2))*SIN(B6))/SQRT(1+'1.설계입력'!$C$39^2-2*'1.설계입력'!$C$39*COS(B6))) -> 0.0112 | M6: 표준 최소 반경 | N6: =MIN(I6:I1805) -> 76.5 | O6: 이론값 r_p - r_rp - a 와 같아야 함
A7: =A6+'1.설계입력'!$C$12 -> 0.2 | B7: =RADIANS(A7) -> 0.0034906585 | C7: =ATAN2('1.설계입력'!$C$6/('1.설계입력'!$C$8*'1.설계입력'!$C$15)-COS((1-'1.설계입력'!$C$15)*B7),SIN((1-'1.설계입력'!$C$15)*B7)) -> -0.34646146 | D7: ='1.설계입력'!$C$6*COS(B7)-'1.설계입력'!$C$7*COS(B7+C7)-'1.설계입력'!$C$8*COS('1.설계입력'!$C$15*B7) -> 76.747059 | E7: =-'1.설계입력'!$C$6*SIN(B7)+'1.설계입력'!$C$7*SIN(B7+C7)+'1.설계입력'!$C$8*SIN('1.설계입력'!$C$15*B7) -> -1.4226192 | F7: =ATAN2(('1.설계입력'!$C$6+'1.설계입력'!$C$33)/('1.설계입력'!$C$8*'1.설계입력'!$C$15)-COS((1-'1.설계입력'!$C$15)*B7),SIN((1-'1.설계입력'!$C$15)*B7)) -> -0.34650536 | G7: =('1.설계입력'!$C$6+'1.설계입력'!$C$33)*COS(B7)-('1.설계입력'!$C$7+'1.설계입력'!$C$34)*COS(B7+F7)-'1.설계입력'!$C$8*COS('1.설계입력'!$C$15*B7) -> 76.73639 | H7: =-('1.설계입력'!$C$6+'1.설계입력'!$C$33)*SIN(B7)+('1.설계입력'!$C$7+'1.설계입력'!$C$34)*SIN(B7+F7)+'1.설계입력'!$C$8*SIN('1.설계입력'!$C$15*B7) -> -1.425498 | I7: =SQRT(D7^2+E7^2) -> 76.760243 | J7: =SQRT(G7^2+H7^2) -> 76.749629 | K7: =IF(OR(A7>180,'1.설계입력'!$C$39>=1),"",'1.설계입력'!$C$34*(1-SIN(B7)/SQRT(1+'1.설계입력'!$C$39^2-2*'1.설계입력'!$C$39*COS(B7)))-'1.설계입력'!$C$33*(1-'1.설계입력'!$C$39*COS(B7)-SQRT(MAX(0,1-'1.설계입력'!$C$39^2))*SIN(B7))/SQRT(1+'1.설계입력'!$C$39^2-2*'1.설계입력'!$C$39*COS(B7))) -> 0.011066978 | M7: 표준 꽃잎 깊이 | N7: =MAX(I6:I1805)-MIN(I6:I1805) -> 3 | O7: 이론값 2a 와 같아야 함
A8: =A7+'1.설계입력'!$C$12 -> 0.4 | B8: =RADIANS(A8) -> 0.006981317 | C8: =ATAN2('1.설계입력'!$C$6/('1.설계입력'!$C$8*'1.설계입력'!$C$15)-COS((1-'1.설계입력'!$C$15)*B8),SIN((1-'1.설계입력'!$C$15)*B8)) -> -0.58786033 | D8: ='1.설계입력'!$C$6*COS(B8)-'1.설계입력'!$C$7*COS(B8+C8)-'1.설계입력'!$C$8*COS('1.설계입력'!$C$15*B8) -> 77.212187 | E8: =-'1.설계입력'!$C$6*SIN(B8)+'1.설계입력'!$C$7*SIN(B8+C8)+'1.설계입력'!$C$8*SIN('1.설계입력'!$C$15*B8) -> -2.3540433 | F8: =ATAN2(('1.설계입력'!$C$6+'1.설계입력'!$C$33)/('1.설계입력'!$C$8*'1.설계입력'!$C$15)-COS((1-'1.설계입력'!$C$15)*B8),SIN((1-'1.설계입력'!$C$15)*B8)) -> -0.58791943 | G8: =('1.설계입력'!$C$6+'1.설계입력'!$C$33)*COS(B8)-('1.설계입력'!$C$7+'1.설계입력'!$C$34)*COS(B8+F8)-'1.설계입력'!$C$8*COS('1.설계입력'!$C$15*B8) -> 77.202445 | H8: =-('1.설계입력'!$C$6+'1.설계입력'!$C$33)*SIN(B8)+('1.설계입력'!$C$7+'1.설계입력'!$C$34)*SIN(B8+F8)+'1.설계입력'!$C$8*SIN('1.설계입력'!$C$15*B8) -> -2.3586646 | I8: =SQRT(D8^2+E8^2) -> 77.248063 | J8: =SQRT(G8^2+H8^2) -> 77.238468 | K8: =IF(OR(A8>180,'1.설계입력'!$C$39>=1),"",'1.설계입력'!$C$34*(1-SIN(B8)/SQRT(1+'1.설계입력'!$C$39^2-2*'1.설계입력'!$C$39*COS(B8)))-'1.설계입력'!$C$33*(1-'1.설계입력'!$C$39*COS(B8)-SQRT(MAX(0,1-'1.설계입력'!$C$39^2))*SIN(B8))/SQRT(1+'1.설계입력'!$C$39^2-2*'1.설계입력'!$C$39*COS(B8))) -> 0.010933725 | M8: 이론 최대반경 | N8: ='1.설계입력'!$C$6-'1.설계입력'!$C$7+'1.설계입력'!$C$8 -> 79.5 | O8: r_p - r_rp + a
A9: =A8+'1.설계입력'!$C$12 -> 0.6 | B9: =RADIANS(A9) -> 0.010471976 | C9: =ATAN2('1.설계입력'!$C$6/('1.설계입력'!$C$8*'1.설계입력'!$C$15)-COS((1-'1.설계입력'!$C$15)*B9),SIN((1-'1.설계입력'!$C$15)*B9)) -> -0.72429173 | D9: ='1.설계입력'!$C$6*COS(B9)-'1.설계입력'!$C$7*COS(B9+C9)-'1.설계입력'!$C$8*COS('1.설계입력'!$C$15*B9) -> 77.60172 | E9: =-'1.설계입력'!$C$6*SIN(B9)+'1.설계입력'!$C$7*SIN(B9+C9)+'1.설계입력'!$C$8*SIN('1.설계입력'!$C$15*B9) -> -2.8674844 | F9: =ATAN2(('1.설계입력'!$C$6+'1.설계입력'!$C$33)/('1.설계입력'!$C$8*'1.설계입력'!$C$15)-COS((1-'1.설계입력'!$C$15)*B9),SIN((1-'1.설계입력'!$C$15)*B9)) -> -0.72434885 | G9: =('1.설계입력'!$C$6+'1.설계입력'!$C$33)*COS(B9)-('1.설계입력'!$C$7+'1.설계입력'!$C$34)*COS(B9+F9)-'1.설계입력'!$C$8*COS('1.설계입력'!$C$15*B9) -> 77.592647 | H9: =-('1.설계입력'!$C$6+'1.설계입력'!$C$33)*SIN(B9)+('1.설계입력'!$C$7+'1.설계입력'!$C$34)*SIN(B9+F9)+'1.설계입력'!$C$8*SIN('1.설계입력'!$C$15*B9) -> -2.8729283 | I9: =SQRT(D9^2+E9^2) -> 77.65468 | J9: =SQRT(G9^2+H9^2) -> 77.645815 | K9: =IF(OR(A9>180,'1.설계입력'!$C$39>=1),"",'1.설계입력'!$C$34*(1-SIN(B9)/SQRT(1+'1.설계입력'!$C$39^2-2*'1.설계입력'!$C$39*COS(B9)))-'1.설계입력'!$C$33*(1-'1.설계입력'!$C$39*COS(B9)-SQRT(MAX(0,1-'1.설계입력'!$C$39^2))*SIN(B9))/SQRT(1+'1.설계입력'!$C$39^2-2*'1.설계입력'!$C$39*COS(B9))) -> 0.010800295 | M9: 이론 최소반경 | N9: ='1.설계입력'!$C$6-'1.설계입력'!$C$7-'1.설계입력'!$C$8 -> 76.5 | O9: r_p - r_rp - a
A10: =A9+'1.설계입력'!$C$12 -> 0.8 | B10: =RADIANS(A10) -> 0.013962634 | C10: =ATAN2('1.설계입력'!$C$6/('1.설계입력'!$C$8*'1.설계입력'!$C$15)-COS((1-'1.설계입력'!$C$15)*B10),SIN((1-'1.설계입력'!$C$15)*B10)) -> -0.79193106 | D10: ='1.설계입력'!$C$6*COS(B10)-'1.설계입력'!$C$7*COS(B10+C10)-'1.설계입력'!$C$8*COS('1.설계입력'!$C$15*B10) -> 77.870572 | E10: =-'1.설계입력'!$C$6*SIN(B10)+'1.설계입력'!$C$7*SIN(B10+C10)+'1.설계입력'!$C$8*SIN('1.설계입력'!$C$15*B10) -> -3.1573547 | F10: =ATAN2(('1.설계입력'!$C$6+'1.설계입력'!$C$33)/('1.설계입력'!$C$8*'1.설계입력'!$C$15)-COS((1-'1.설계입력'!$C$15)*B10),SIN((1-'1.설계입력'!$C$15)*B10)) -> -0.79198159 | G10: =('1.설계입력'!$C$6+'1.설계입력'!$C$33)*COS(B10)-('1.설계입력'!$C$7+'1.설계입력'!$C$34)*COS(B10+F10)-'1.설계입력'!$C$8*COS('1.설계입력'!$C$15*B10) -> 77.861844 | H10: =-('1.설계입력'!$C$6+'1.설계입력'!$C$33)*SIN(B10)+('1.설계입력'!$C$7+'1.설계입력'!$C$34)*SIN(B10+F10)+'1.설계입력'!$C$8*SIN('1.설계입력'!$C$15*B10) -> -3.1631405 | I10: =SQRT(D10^2+E10^2) -> 77.934555 | J10: =SQRT(G10^2+H10^2) -> 77.926069 | K10: =IF(OR(A10>180,'1.설계입력'!$C$39>=1),"",'1.설계입력'!$C$34*(1-SIN(B10)/SQRT(1+'1.설계입력'!$C$39^2-2*'1.설계입력'!$C$39*COS(B10)))-'1.설계입력'!$C$33*(1-'1.설계입력'!$C$39*COS(B10)-SQRT(MAX(0,1-'1.설계입력'!$C$39^2))*SIN(B10))/SQRT(1+'1.설계입력'!$C$39^2-2*'1.설계입력'!$C$39*COS(B10))) -> 0.010666737 | M10: 이론 꽃잎깊이 | N10: =2*'1.설계입력'!$C$8 -> 3 | O10: 2a
A11: =A10+'1.설계입력'!$C$12 -> 1 | B11: =RADIANS(A11) -> 0.017453293 | C11: =ATAN2('1.설계입력'!$C$6/('1.설계입력'!$C$8*'1.설계입력'!$C$15)-COS((1-'1.설계입력'!$C$15)*B11),SIN((1-'1.설계입력'!$C$15)*B11)) -> -0.81804028 | D11: ='1.설계입력'!$C$6*COS(B11)-'1.설계입력'!$C$7*COS(B11+C11)-'1.설계입력'!$C$8*COS('1.설계입력'!$C$15*B11) -> 78.053302 | E11: =-'1.설계입력'!$C$6*SIN(B11)+'1.설계입력'!$C$7*SIN(B11+C11)+'1.설계입력'!$C$8*SIN('1.설계입력'!$C$15*B11) -> -3.3379756 | F11: =ATAN2(('1.설계입력'!$C$6+'1.설계입력'!$C$33)/('1.설계입력'!$C$8*'1.설계입력'!$C$15)-COS((1-'1.설계입력'!$C$15)*B11),SIN((1-'1.설계입력'!$C$15)*B11)) -> -0.81808401 | G11: =('1.설계입력'!$C$6+'1.설계입력'!$C$33)*COS(B11)-('1.설계입력'!$C$7+'1.설계입력'!$C$34)*COS(B11+F11)-'1.설계입력'!$C$8*COS('1.설계입력'!$C$15*B11) -> 78.044689 | H11: =-('1.설계입력'!$C$6+'1.설계입력'!$C$33)*SIN(B11)+('1.설계입력'!$C$7+'1.설계입력'!$C$34)*SIN(B11+F11)+'1.설계입력'!$C$8*SIN('1.설계입력'!$C$15*B11) -> -3.3438574 | I11: =SQRT(D11^2+E11^2) -> 78.124645 | J11: =SQRT(G11^2+H11^2) -> 78.11629 | K11: =IF(OR(A11>180,'1.설계입력'!$C$39>=1),"",'1.설계입력'!$C$34*(1-SIN(B11)/SQRT(1+'1.설계입력'!$C$39^2-2*'1.설계입력'!$C$39*COS(B11)))-'1.설계입력'!$C$33*(1-'1.설계입력'!$C$39*COS(B11)-SQRT(MAX(0,1-'1.설계입력'!$C$39^2))*SIN(B11))/SQRT(1+'1.설계입력'!$C$39^2-2*'1.설계입력'!$C$39*COS(B11))) -> 0.010533105 | M11: 수정 최대 반경 | N11: =MAX(J6:J1805) -> 79.4888 | O11: 표준보다 약간 작아야 함
A12: =A11+'1.설계입력'!$C$12 -> 1.2 | B12: =RADIANS(A12) -> 0.020943951 | C12: =ATAN2('1.설계입력'!$C$6/('1.설계입력'!$C$8*'1.설계입력'!$C$15)-COS((1-'1.설계입력'!$C$15)*B12),SIN((1-'1.설계입력'!$C$15)*B12)) -> -0.81858664 | D12: ='1.설계입력'!$C$6*COS(B12)-'1.설계입력'!$C$7*COS(B12+C12)-'1.설계입력'!$C$8*COS('1.설계입력'!$C$15*B12) -> 78.184737 | E12: =-'1.설계입력'!$C$6*SIN(B12)+'1.설계입력'!$C$7*SIN(B12+C12)+'1.설계입력'!$C$8*SIN('1.설계입력'!$C$15*B12) -> -3.4654082 | F12: =ATAN2(('1.설계입력'!$C$6+'1.설계입력'!$C$33)/('1.설계입력'!$C$8*'1.설계입력'!$C$15)-COS((1-'1.설계입력'!$C$15)*B12),SIN((1-'1.설계입력'!$C$15)*B12)) -> -0.81862443 | G12: =('1.설계입력'!$C$6+'1.설계입력'!$C$33)*COS(B12)-('1.설계입력'!$C$7+'1.설계입력'!$C$34)*COS(B12+F12)-'1.설계입력'!$C$8*COS('1.설계입력'!$C$15*B12) -> 78.176089 | H12: =-('1.설계입력'!$C$6+'1.설계입력'!$C$33)*SIN(B12)+('1.설계입력'!$C$7+'1.설계입력'!$C$34)*SIN(B12+F12)+'1.설계입력'!$C$8*SIN('1.설계입력'!$C$15*B12) -> -3.4712463 | I12: =SQRT(D12^2+E12^2) -> 78.261498 | J12: =SQRT(G12^2+H12^2) -> 78.253118 | K12: =IF(OR(A12>180,'1.설계입력'!$C$39>=1),"",'1.설계입력'!$C$34*(1-SIN(B12)/SQRT(1+'1.설계입력'!$C$39^2-2*'1.설계입력'!$C$39*COS(B12)))-'1.설계입력'!$C$33*(1-'1.설계입력'!$C$39*COS(B12)-SQRT(MAX(0,1-'1.설계입력'!$C$39^2))*SIN(B12))/SQRT(1+'1.설계입력'!$C$39^2-2*'1.설계입력'!$C$39*COS(B12))) -> 0.010399449 | M12: 수정 최소 반경 | N12: =MIN(J6:J1805) -> 76.4888 | O12: 표준보다 약간 작아야 함
A13: =A12+'1.설계입력'!$C$12 -> 1.4 | B13: =RADIANS(A13) -> 0.02443461 | C13: =ATAN2('1.설계입력'!$C$6/('1.설계입력'!$C$8*'1.설계입력'!$C$15)-COS((1-'1.설계입력'!$C$15)*B13),SIN((1-'1.설계입력'!$C$15)*B13)) -> -0.80270818 | D13: ='1.설계입력'!$C$6*COS(B13)-'1.설계입력'!$C$7*COS(B13+C13)-'1.설계입력'!$C$8*COS('1.설계입력'!$C$15*B13) -> 78.288226 | E13: =-'1.설계입력'!$C$6*SIN(B13)+'1.설계입력'!$C$7*SIN(B13+C13)+'1.설계입력'!$C$8*SIN('1.설계입력'!$C$15*B13) -> -3.5680864 | F13: =ATAN2(('1.설계입력'!$C$6+'1.설계입력'!$C$33)/('1.설계입력'!$C$8*'1.설계입력'!$C$15)-COS((1-'1.설계입력'!$C$15)*B13),SIN((1-'1.설계입력'!$C$15)*B13)) -> -0.80274097 | G13: =('1.설계입력'!$C$6+'1.설계입력'!$C$33)*COS(B13)-('1.설계입력'!$C$7+'1.설계입력'!$C$34)*COS(B13+F13)-'1.설계입력'!$C$8*COS('1.설계입력'!$C$15*B13) -> 78.279451 | H13: =-('1.설계입력'!$C$6+'1.설계입력'!$C$33)*SIN(B13)+('1.설계입력'!$C$7+'1.설계입력'!$C$34)*SIN(B13+F13)+'1.설계입력'!$C$8*SIN('1.설계입력'!$C$15*B13) -> -3.5737908 | I13: =SQRT(D13^2+E13^2) -> 78.369494 | J13: =SQRT(G13^2+H13^2) -> 78.360988 | K13: =IF(OR(A13>180,'1.설계입력'!$C$39>=1),"",'1.설계입력'!$C$34*(1-SIN(B13)/SQRT(1+'1.설계입력'!$C$39^2-2*'1.설계입력'!$C$39*COS(B13)))-'1.설계입력'!$C$33*(1-'1.설계입력'!$C$39*COS(B13)-SQRT(MAX(0,1-'1.설계입력'!$C$39^2))*SIN(B13))/SQRT(1+'1.설계입력'!$C$39^2-2*'1.설계입력'!$C$39*COS(B13))) -> 0.01026582 | M13: 반경 감소량 | N13: =MAX(I6:I1805)-MAX(J6:J1805) -> 0.0112 | O13: 수정으로 줄어든 반경. 수 um 수준
A14: =A13+'1.설계입력'!$C$12 -> 1.6 | B14: =RADIANS(A14) -> 0.027925268 | C14: =ATAN2('1.설계입력'!$C$6/('1.설계입력'!$C$8*'1.설계입력'!$C$15)-COS((1-'1.설계입력'!$C$15)*B14),SIN((1-'1.설계입력'!$C$15)*B14)) -> -0.77580564 | D14: ='1.설계입력'!$C$6*COS(B14)-'1.설계입력'!$C$7*COS(B14+C14)-'1.설계입력'!$C$8*COS('1.설계입력'!$C$15*B14) -> 78.377945 | E14: =-'1.설계입력'!$C$6*SIN(B14)+'1.설계입력'!$C$7*SIN(B14+C14)+'1.설계입력'!$C$8*SIN('1.설계입력'!$C$15*B14) -> -3.6617286 | F14: =ATAN2(('1.설계입력'!$C$6+'1.설계입력'!$C$33)/('1.설계입력'!$C$8*'1.설계입력'!$C$15)-COS((1-'1.설계입력'!$C$15)*B14),SIN((1-'1.설계입력'!$C$15)*B14)) -> -0.77583424 | G14: =('1.설계입력'!$C$6+'1.설계입력'!$C$33)*COS(B14)-('1.설계입력'!$C$7+'1.설계입력'!$C$34)*COS(B14+F14)-'1.설계입력'!$C$8*COS('1.설계입력'!$C$15*B14) -> 78.368985 | H14: =-('1.설계입력'!$C$6+'1.설계입력'!$C$33)*SIN(B14)+('1.설계입력'!$C$7+'1.설계입력'!$C$34)*SIN(B14+F14)+'1.설계입력'!$C$8*SIN('1.설계입력'!$C$15*B14) -> -3.6672348 | I14: =SQRT(D14^2+E14^2) -> 78.463434 | J14: =SQRT(G14^2+H14^2) -> 78.454742 | K14: =IF(OR(A14>180,'1.설계입력'!$C$39>=1),"",'1.설계입력'!$C$34*(1-SIN(B14)/SQRT(1+'1.설계입력'!$C$39^2-2*'1.설계입력'!$C$39*COS(B14)))-'1.설계입력'!$C$33*(1-'1.설계입력'!$C$39*COS(B14)-SQRT(MAX(0,1-'1.설계입력'!$C$39^2))*SIN(B14))/SQRT(1+'1.설계입력'!$C$39^2-2*'1.설계입력'!$C$39*COS(B14))) -> 0.010132271 | M14: 최대 초기틈새 | N14: =MAX(K6:K1805) -> 0.0112 | O14: 논문B 식(20). 수 um 수준이어야 함
A15: =A14+'1.설계입력'!$C$12 -> 1.8 | B15: =RADIANS(A15) -> 0.031415927 | C15: =ATAN2('1.설계입력'!$C$6/('1.설계입력'!$C$8*'1.설계입력'!$C$15)-COS((1-'1.설계입력'!$C$15)*B15),SIN((1-'1.설계입력'!$C$15)*B15)) -> -0.74121343 | D15: ='1.설계입력'!$C$6*COS(B15)-'1.설계입력'!$C$7*COS(B15+C15)-'1.설계입력'!$C$8*COS('1.설계입력'!$C$15*B15) -> 78.462037 | E15: =-'1.설계입력'!$C$6*SIN(B15)+'1.설계입력'!$C$7*SIN(B15+C15)+'1.설계입력'!$C$8*SIN('1.설계입력'!$C$15*B15) -> -3.7558182 | F15: =ATAN2(('1.설계입력'!$C$6+'1.설계입력'!$C$33)/('1.설계입력'!$C$8*'1.설계입력'!$C$15)-COS((1-'1.설계입력'!$C$15)*B15),SIN((1-'1.설계입력'!$C$15)*B15)) -> -0.74123846 | G15: =('1.설계입력'!$C$6+'1.설계입력'!$C$33)*COS(B15)-('1.설계입력'!$C$7+'1.설계입력'!$C$34)*COS(B15+F15)-'1.설계입력'!$C$8*COS('1.설계입력'!$C$15*B15) -> 78.45286 | H15: =-('1.설계입력'!$C$6+'1.설계입력'!$C$33)*SIN(B15)+('1.설계입력'!$C$7+'1.설계입력'!$C$34)*SIN(B15+F15)+'1.설계입력'!$C$8*SIN('1.설계입력'!$C$15*B15) -> -3.7610756 | I15: =SQRT(D15^2+E15^2) -> 78.551877 | J15: =SQRT(G15^2+H15^2) -> 78.542962 | K15: =IF(OR(A15>180,'1.설계입력'!$C$39>=1),"",'1.설계입력'!$C$34*(1-SIN(B15)/SQRT(1+'1.설계입력'!$C$39^2-2*'1.설계입력'!$C$39*COS(B15)))-'1.설계입력'!$C$33*(1-'1.설계입력'!$C$39*COS(B15)-SQRT(MAX(0,1-'1.설계입력'!$C$39^2))*SIN(B15))/SQRT(1+'1.설계입력'!$C$39^2-2*'1.설계입력'!$C$39*COS(B15))) -> 0.0099988526 | M15: 계산 점 수 | N15: =COUNT(A6:A1805) -> 1800 | O15: phi 스텝에 따라 결정
A16: =A15+'1.설계입력'!$C$12 -> 2 | B16: =RADIANS(A16) -> 0.034906585 | C16: =ATAN2('1.설계입력'!$C$6/('1.설계입력'!$C$8*'1.설계입력'!$C$15)-COS((1-'1.설계입력'!$C$15)*B16),SIN((1-'1.설계입력'!$C$15)*B16)) -> -0.70108025 | D16: ='1.설계입력'!$C$6*COS(B16)-'1.설계입력'!$C$7*COS(B16+C16)-'1.설계입력'!$C$8*COS('1.설계입력'!$C$15*B16) -> 78.544807 | E16: =-'1.설계입력'!$C$6*SIN(B16)+'1.설계입력'!$C$7*SIN(B16+C16)+'1.설계입력'!$C$8*SIN('1.설계입력'!$C$15*B16) -> -3.8564762 | F16: =ATAN2(('1.설계입력'!$C$6+'1.설계입력'!$C$33)/('1.설계입력'!$C$8*'1.설계입력'!$C$15)-COS((1-'1.설계입력'!$C$15)*B16),SIN((1-'1.설계입력'!$C$15)*B16)) -> -0.70110223 | G16: =('1.설계입력'!$C$6+'1.설계입력'!$C$33)*COS(B16)-('1.설계입력'!$C$7+'1.설계입력'!$C$34)*COS(B16+F16)-'1.설계입력'!$C$8*COS('1.설계입력'!$C$15*B16) -> 78.535396 | H16: =-('1.설계입력'!$C$6+'1.설계입력'!$C$33)*SIN(B16)+('1.설계입력'!$C$7+'1.설계입력'!$C$34)*SIN(B16+F16)+'1.설계입력'!$C$8*SIN('1.설계입력'!$C$15*B16) -> -3.861443 | I16: =SQRT(D16^2+E16^2) -> 78.639425 | J16: =SQRT(G16^2+H16^2) -> 78.630268 | K16: =IF(OR(A16>180,'1.설계입력'!$C$39>=1),"",'1.설계입력'!$C$34*(1-SIN(B16)/SQRT(1+'1.설계입력'!$C$39^2-2*'1.설계입력'!$C$39*COS(B16)))-'1.설계입력'!$C$33*(1-'1.설계입력'!$C$39*COS(B16)-SQRT(MAX(0,1-'1.설계입력'!$C$39^2))*SIN(B16))/SQRT(1+'1.설계입력'!$C$39^2-2*'1.설계입력'!$C$39*COS(B16))) -> 0.0098656147
A17: =A16+'1.설계입력'!$C$12 -> 2.2 | B17: =RADIANS(A17) -> 0.038397244 | C17: =ATAN2('1.설계입력'!$C$6/('1.설계입력'!$C$8*'1.설계입력'!$C$15)-COS((1-'1.설계입력'!$C$15)*B17),SIN((1-'1.설계입력'!$C$15)*B17)) -> -0.65684554 | D17: ='1.설계입력'!$C$6*COS(B17)-'1.설계입력'!$C$7*COS(B17+C17)-'1.설계입력'!$C$8*COS('1.설계입력'!$C$15*B17) -> 78.628094 | E17: =-'1.설계입력'!$C$6*SIN(B17)+'1.설계입력'!$C$7*SIN(B17+C17)+'1.설계입력'!$C$8*SIN('1.설계입력'!$C$15*B17) -> -3.9678004 | F17: =ATAN2(('1.설계입력'!$C$6+'1.설계입력'!$C$33)/('1.설계입력'!$C$8*'1.설계입력'!$C$15)-COS((1-'1.설계입력'!$C$15)*B17),SIN((1-'1.설계입력'!$C$15)*B17)) -> -0.65686485 | G17: =('1.설계입력'!$C$6+'1.설계입력'!$C$33)*COS(B17)-('1.설계입력'!$C$7+'1.설계입력'!$C$34)*COS(B17+F17)-'1.설계입력'!$C$8*COS('1.설계입력'!$C$15*B17) -> 78.618441 | H17: =-('1.설계입력'!$C$6+'1.설계입력'!$C$33)*SIN(B17)+('1.설계입력'!$C$7+'1.설계입력'!$C$34)*SIN(B17+F17)+'1.설계입력'!$C$8*SIN('1.설계입력'!$C$15*B17) -> -3.9724406 | I17: =SQRT(D17^2+E17^2) -> 78.728143 | J17: =SQRT(G17^2+H17^2) -> 78.718737 | K17: =IF(OR(A17>180,'1.설계입력'!$C$39>=1),"",'1.설계입력'!$C$34*(1-SIN(B17)/SQRT(1+'1.설계입력'!$C$39^2-2*'1.설계입력'!$C$39*COS(B17)))-'1.설계입력'!$C$33*(1-'1.설계입력'!$C$39*COS(B17)-SQRT(MAX(0,1-'1.설계입력'!$C$39^2))*SIN(B17))/SQRT(1+'1.설계입력'!$C$39^2-2*'1.설계입력'!$C$39*COS(B17))) -> 0.0097326076 | M17: 치형 검증
A18: =A17+'1.설계입력'!$C$12 -> 2.4 | B18: =RADIANS(A18) -> 0.041887902 | C18: =ATAN2('1.설계입력'!$C$6/('1.설계입력'!$C$8*'1.설계입력'!$C$15)-COS((1-'1.설계입력'!$C$15)*B18),SIN((1-'1.설계입력'!$C$15)*B18)) -> -0.60950735 | D18: ='1.설계입력'!$C$6*COS(B18)-'1.설계입력'!$C$7*COS(B18+C18)-'1.설계입력'!$C$8*COS('1.설계입력'!$C$15*B18) -> 78.712132 | E18: =-'1.설계입력'!$C$6*SIN(B18)+'1.설계입력'!$C$7*SIN(B18+C18)+'1.설계입력'!$C$8*SIN('1.설계입력'!$C$15*B18) -> -4.0925261 | F18: =ATAN2(('1.설계입력'!$C$6+'1.설계입력'!$C$33)/('1.설계입력'!$C$8*'1.설계입력'!$C$15)-COS((1-'1.설계입력'!$C$15)*B18),SIN((1-'1.설계입력'!$C$15)*B18)) -> -0.60952432 | G18: =('1.설계입력'!$C$6+'1.설계입력'!$C$33)*COS(B18)-('1.설계입력'!$C$7+'1.설계입력'!$C$34)*COS(B18+F18)-'1.설계입력'!$C$8*COS('1.설계입력'!$C$15*B18) -> 78.702241 | H18: =-('1.설계입력'!$C$6+'1.설계입력'!$C$33)*SIN(B18)+('1.설계입력'!$C$7+'1.설계입력'!$C$34)*SIN(B18+F18)+'1.설계입력'!$C$8*SIN('1.설계입력'!$C$15*B18) -> -4.0968084 | I18: =SQRT(D18^2+E18^2) -> 78.818453 | J18: =SQRT(G18^2+H18^2) -> 78.808798 | K18: =IF(OR(A18>180,'1.설계입력'!$C$39>=1),"",'1.설계입력'!$C$34*(1-SIN(B18)/SQRT(1+'1.설계입력'!$C$39^2-2*'1.설계입력'!$C$39*COS(B18)))-'1.설계입력'!$C$33*(1-'1.설계입력'!$C$39*COS(B18)-SQRT(MAX(0,1-'1.설계입력'!$C$39^2))*SIN(B18))/SQRT(1+'1.설계입력'!$C$39^2-2*'1.설계입력'!$C$39*COS(B18))) -> 0.0095998808 | M18: 최대반경 일치 | N18: =IF(ABS(N5-N8)<0.0001,"통과","불일치") -> 통과 | O18: 표준 계산값이 r_p-r_rp+a 와 맞는가
A19: =A18+'1.설계입력'!$C$12 -> 2.6 | B19: =RADIANS(A19) -> 0.045378561 | C19: =ATAN2('1.설계입력'!$C$6/('1.설계입력'!$C$8*'1.설계입력'!$C$15)-COS((1-'1.설계입력'!$C$15)*B19),SIN((1-'1.설계입력'!$C$15)*B19)) -> -0.55977923 | D19: ='1.설계입력'!$C$6*COS(B19)-'1.설계입력'!$C$7*COS(B19+C19)-'1.설계입력'!$C$8*COS('1.설계입력'!$C$15*B19) -> 78.796119 | E19: =-'1.설계입력'!$C$6*SIN(B19)+'1.설계입력'!$C$7*SIN(B19+C19)+'1.설계입력'!$C$8*SIN('1.설계입력'!$C$15*B19) -> -4.2323741 | F19: =ATAN2(('1.설계입력'!$C$6+'1.설계입력'!$C$33)/('1.설계입력'!$C$8*'1.설계입력'!$C$15)-COS((1-'1.설계입력'!$C$15)*B19),SIN((1-'1.설계입력'!$C$15)*B19)) -> -0.55979409 | G19: =('1.설계입력'!$C$6+'1.설계입력'!$C$33)*COS(B19)-('1.설계입력'!$C$7+'1.설계입력'!$C$34)*COS(B19+F19)-'1.설계입력'!$C$8*COS('1.설계입력'!$C$15*B19) -> 78.785999 | H19: =-('1.설계입력'!$C$6+'1.설계입력'!$C$33)*SIN(B19)+('1.설계입력'!$C$7+'1.설계입력'!$C$34)*SIN(B19+F19)+'1.설계입력'!$C$8*SIN('1.설계입력'!$C$15*B19) -> -4.2362707 | I19: =SQRT(D19^2+E19^2) -> 78.909703 | J19: =SQRT(G19^2+H19^2) -> 78.899808 | K19: =IF(OR(A19>180,'1.설계입력'!$C$39>=1),"",'1.설계입력'!$C$34*(1-SIN(B19)/SQRT(1+'1.설계입력'!$C$39^2-2*'1.설계입력'!$C$39*COS(B19)))-'1.설계입력'!$C$33*(1-'1.설계입력'!$C$39*COS(B19)-SQRT(MAX(0,1-'1.설계입력'!$C$39^2))*SIN(B19))/SQRT(1+'1.설계입력'!$C$39^2-2*'1.설계입력'!$C$39*COS(B19))) -> 0.0094674832 | M19: 최소반경 일치 | N19: =IF(ABS(N6-N9)<0.0001,"통과","불일치") -> 통과 | O19: 표준 계산값이 r_p-r_rp-a 와 맞는가
A20: =A19+'1.설계입력'!$C$12 -> 2.8 | B20: =RADIANS(A20) -> 0.048869219 | C20: =ATAN2('1.설계입력'!$C$6/('1.설계입력'!$C$8*'1.설계입력'!$C$15)-COS((1-'1.설계입력'!$C$15)*B20),SIN((1-'1.설계입력'!$C$15)*B20)) -> -0.50818554 | D20: ='1.설계입력'!$C$6*COS(B20)-'1.설계입력'!$C$7*COS(B20+C20)-'1.설계입력'!$C$8*COS('1.설계입력'!$C$15*B20) -> 78.87859 | E20: =-'1.설계입력'!$C$6*SIN(B20)+'1.설계입력'!$C$7*SIN(B20+C20)+'1.설계입력'!$C$8*SIN('1.설계입력'!$C$15*B20) -> -4.3882469 | F20: =ATAN2(('1.설계입력'!$C$6+'1.설계입력'!$C$33)/('1.설계입력'!$C$8*'1.설계입력'!$C$15)-COS((1-'1.설계입력'!$C$15)*B20),SIN((1-'1.설계입력'!$C$15)*B20)) -> -0.50819849 | G20: =('1.설계입력'!$C$6+'1.설계입력'!$C$33)*COS(B20)-('1.설계입력'!$C$7+'1.설계입력'!$C$34)*COS(B20+F20)-'1.설계입력'!$C$8*COS('1.설계입력'!$C$15*B20) -> 78.868256 | H20: =-('1.설계입력'!$C$6+'1.설계입력'!$C$33)*SIN(B20)+('1.설계입력'!$C$7+'1.설계입력'!$C$34)*SIN(B20+F20)+'1.설계입력'!$C$8*SIN('1.설계입력'!$C$15*B20) -> -4.391733 | I20: =SQRT(D20^2+E20^2) -> 79.000561 | J20: =SQRT(G20^2+H20^2) -> 78.990437 | K20: =IF(OR(A20>180,'1.설계입력'!$C$39>=1),"",'1.설계입력'!$C$34*(1-SIN(B20)/SQRT(1+'1.설계입력'!$C$39^2-2*'1.설계입력'!$C$39*COS(B20)))-'1.설계입력'!$C$33*(1-'1.설계입력'!$C$39*COS(B20)-SQRT(MAX(0,1-'1.설계입력'!$C$39^2))*SIN(B20))/SQRT(1+'1.설계입력'!$C$39^2-2*'1.설계입력'!$C$39*COS(B20))) -> 0.0093354629 | M20: 꽃잎깊이 = 2a | N20: =IF(ABS(N7-N10)<0.0001,"통과","불일치") -> 통과 | O20: 꽃잎 깊이가 편심의 2배인가
A21: =A20+'1.설계입력'!$C$12 -> 3 | B21: =RADIANS(A21) -> 0.052359878 | C21: =ATAN2('1.설계입력'!$C$6/('1.설계입력'!$C$8*'1.설계입력'!$C$15)-COS((1-'1.설계입력'!$C$15)*B21),SIN((1-'1.설계입력'!$C$15)*B21)) -> -0.45512147 | D21: ='1.설계입력'!$C$6*COS(B21)-'1.설계입력'!$C$7*COS(B21+C21)-'1.설계입력'!$C$8*COS('1.설계입력'!$C$15*B21) -> 78.957694 | E21: =-'1.설계입력'!$C$6*SIN(B21)+'1.설계입력'!$C$7*SIN(B21+C21)+'1.설계입력'!$C$8*SIN('1.설계입력'!$C$15*B21) -> -4.5603521 | F21: =ATAN2(('1.설계입력'!$C$6+'1.설계입력'!$C$33)/('1.설계입력'!$C$8*'1.설계입력'!$C$15)-COS((1-'1.설계입력'!$C$15)*B21),SIN((1-'1.설계입력'!$C$15)*B21)) -> -0.45513268 | G21: =('1.설계입력'!$C$6+'1.설계입력'!$C$33)*COS(B21)-('1.설계입력'!$C$7+'1.설계입력'!$C$34)*COS(B21+F21)-'1.설계입력'!$C$8*COS('1.설계입력'!$C$15*B21) -> 78.947164 | H21: =-('1.설계입력'!$C$6+'1.설계입력'!$C$33)*SIN(B21)+('1.설계입력'!$C$7+'1.설계입력'!$C$34)*SIN(B21+F21)+'1.설계입력'!$C$8*SIN('1.설계입력'!$C$15*B21) -> -4.5634061 | I21: =SQRT(D21^2+E21^2) -> 79.08928 | J21: =SQRT(G21^2+H21^2) -> 79.078944 | K21: =IF(OR(A21>180,'1.설계입력'!$C$39>=1),"",'1.설계입력'!$C$34*(1-SIN(B21)/SQRT(1+'1.설계입력'!$C$39^2-2*'1.설계입력'!$C$39*COS(B21)))-'1.설계입력'!$C$33*(1-'1.설계입력'!$C$39*COS(B21)-SQRT(MAX(0,1-'1.설계입력'!$C$39^2))*SIN(B21))/SQRT(1+'1.설계입력'!$C$39^2-2*'1.설계입력'!$C$39*COS(B21))) -> 0.0092038671 | M21: 수정량 스케일 | N21: =IF(AND(N13>0,N13<0.1),"통과","확인필요") -> 통과 | O21: 반경 감소가 0.1mm 미만인가 (수정은 미세해야 함)
A22: =A21+'1.설계입력'!$C$12 -> 3.2 | B22: =RADIANS(A22) -> 0.055850536 | C22: =ATAN2('1.설계입력'!$C$6/('1.설계입력'!$C$8*'1.설계입력'!$C$15)-COS((1-'1.설계입력'!$C$15)*B22),SIN((1-'1.설계입력'!$C$15)*B22)) -> -0.40089207 | D22: ='1.설계입력'!$C$6*COS(B22)-'1.설계입력'!$C$7*COS(B22+C22)-'1.설계입력'!$C$8*COS('1.설계입력'!$C$15*B22) -> 79.031389 | E22: =-'1.설계입력'!$C$6*SIN(B22)+'1.설계입력'!$C$7*SIN(B22+C22)+'1.설계입력'!$C$8*SIN('1.설계입력'!$C$15*B22) -> -4.7482903 | F22: =ATAN2(('1.설계입력'!$C$6+'1.설계입력'!$C$33)/('1.설계입력'!$C$8*'1.설계입력'!$C$15)-COS((1-'1.설계입력'!$C$15)*B22),SIN((1-'1.설계입력'!$C$15)*B22)) -> -0.40090165 | G22: =('1.설계입력'!$C$6+'1.설계입력'!$C$33)*COS(B22)-('1.설계입력'!$C$7+'1.설계입력'!$C$34)*COS(B22+F22)-'1.설계입력'!$C$8*COS('1.설계입력'!$C$15*B22) -> 79.020684 | H22: =-('1.설계입력'!$C$6+'1.설계입력'!$C$33)*SIN(B22)+('1.설계입력'!$C$7+'1.설계입력'!$C$34)*SIN(B22+F22)+'1.설계입력'!$C$8*SIN('1.설계입력'!$C$15*B22) -> -4.7508931 | I22: =SQRT(D22^2+E22^2) -> 79.173902 | J22: =SQRT(G22^2+H22^2) -> 79.163373 | K22: =IF(OR(A22>180,'1.설계입력'!$C$39>=1),"",'1.설계입력'!$C$34*(1-SIN(B22)/SQRT(1+'1.설계입력'!$C$39^2-2*'1.설계입력'!$C$39*COS(B22)))-'1.설계입력'!$C$33*(1-'1.설계입력'!$C$39*COS(B22)-SQRT(MAX(0,1-'1.설계입력'!$C$39^2))*SIN(B22))/SQRT(1+'1.설계입력'!$C$39^2-2*'1.설계입력'!$C$39*COS(B22))) -> 0.0090727422 | M22: 틈새 스케일 | N22: =IF(AND(N14>0,N14<0.1),"통과","확인필요") -> 통과 | O22: 초기 틈새가 0.1mm 미만인가
A23: =A22+'1.설계입력'!$C$12 -> 3.4 | B23: =RADIANS(A23) -> 0.059341195 | C23: =ATAN2('1.설계입력'!$C$6/('1.설계입력'!$C$8*'1.설계입력'!$C$15)-COS((1-'1.설계입력'!$C$15)*B23),SIN((1-'1.설계입력'!$C$15)*B23)) -> -0.34573827 | D23: ='1.설계입력'!$C$6*COS(B23)-'1.설계입력'!$C$7*COS(B23+C23)-'1.설계입력'!$C$8*COS('1.설계입력'!$C$15*B23) -> 79.097604 | E23: =-'1.설계입력'!$C$6*SIN(B23)+'1.설계입력'!$C$7*SIN(B23+C23)+'1.설계입력'!$C$8*SIN('1.설계입력'!$C$15*B23) -> -4.9511267 | F23: =ATAN2(('1.설계입력'!$C$6+'1.설계입력'!$C$33)/('1.설계입력'!$C$8*'1.설계입력'!$C$15)-COS((1-'1.설계입력'!$C$15)*B23),SIN((1-'1.설계입력'!$C$15)*B23)) -> -0.34574633 | G23: =('1.설계입력'!$C$6+'1.설계입력'!$C$33)*COS(B23)-('1.설계입력'!$C$7+'1.설계입력'!$C$34)*COS(B23+F23)-'1.설계입력'!$C$8*COS('1.설계입력'!$C$15*B23) -> 79.086748 | H23: =-('1.설계입력'!$C$6+'1.설계입력'!$C$33)*SIN(B23)+('1.설계입력'!$C$7+'1.설계입력'!$C$34)*SIN(B23+F23)+'1.설계입력'!$C$8*SIN('1.설계입력'!$C$15*B23) -> -4.953262 | I23: =SQRT(D23^2+E23^2) -> 79.252411 | J23: =SQRT(G23^2+H23^2) -> 79.24171 | K23: =IF(OR(A23>180,'1.설계입력'!$C$39>=1),"",'1.설계입력'!$C$34*(1-SIN(B23)/SQRT(1+'1.설계입력'!$C$39^2-2*'1.설계입력'!$C$39*COS(B23)))-'1.설계입력'!$C$33*(1-'1.설계입력'!$C$39*COS(B23)-SQRT(MAX(0,1-'1.설계입력'!$C$39^2))*SIN(B23))/SQRT(1+'1.설계입력'!$C$39^2-2*'1.설계입력'!$C$39*COS(B23))) -> 0.0089421336
A24: =A23+'1.설계입력'!$C$12 -> 3.6 | B24: =RADIANS(A24) -> 0.062831853 | C24: =ATAN2('1.설계입력'!$C$6/('1.설계입력'!$C$8*'1.설계입력'!$C$15)-COS((1-'1.설계입력'!$C$15)*B24),SIN((1-'1.설계입력'!$C$15)*B24)) -> -0.28985485 | D24: ='1.설계입력'!$C$6*COS(B24)-'1.설계입력'!$C$7*COS(B24+C24)-'1.설계입력'!$C$8*COS('1.설계입력'!$C$15*B24) -> 79.154354 | E24: =-'1.설계입력'!$C$6*SIN(B24)+'1.설계입력'!$C$7*SIN(B24+C24)+'1.설계입력'!$C$8*SIN('1.설계입력'!$C$15*B24) -> -5.1674564 | F24: =ATAN2(('1.설계입력'!$C$6+'1.설계입력'!$C$33)/('1.설계입력'!$C$8*'1.설계입력'!$C$15)-COS((1-'1.설계입력'!$C$15)*B24),SIN((1-'1.설계입력'!$C$15)*B24)) -> -0.28986147 | G24: =('1.설계입력'!$C$6+'1.설계입력'!$C$33)*COS(B24)-('1.설계입력'!$C$7+'1.설계입력'!$C$34)*COS(B24+F24)-'1.설계입력'!$C$8*COS('1.설계입력'!$C$15*B24) -> 79.143374 | H24: =-('1.설계입력'!$C$6+'1.설계입력'!$C$33)*SIN(B24)+('1.설계입력'!$C$7+'1.설계입력'!$C$34)*SIN(B24+F24)+'1.설계입력'!$C$8*SIN('1.설계입력'!$C$15*B24) -> -5.1691107 | I24: =SQRT(D24^2+E24^2) -> 79.322849 | J24: =SQRT(G24^2+H24^2) -> 79.312 | K24: =IF(OR(A24>180,'1.설계입력'!$C$39>=1),"",'1.설계입력'!$C$34*(1-SIN(B24)/SQRT(1+'1.설계입력'!$C$39^2-2*'1.설계입력'!$C$39*COS(B24)))-'1.설계입력'!$C$33*(1-'1.설계입력'!$C$39*COS(B24)-SQRT(MAX(0,1-'1.설계입력'!$C$39^2))*SIN(B24))/SQRT(1+'1.설계입력'!$C$39^2-2*'1.설계입력'!$C$39*COS(B24))) -> 0.0088120857
A25: =A24+'1.설계입력'!$C$12 -> 3.8 | B25: =RADIANS(A25) -> 0.066322512 | C25: =ATAN2('1.설계입력'!$C$6/('1.설계입력'!$C$8*'1.설계입력'!$C$15)-COS((1-'1.설계입력'!$C$15)*B25),SIN((1-'1.설계입력'!$C$15)*B25)) -> -0.23340312 | D25: ='1.설계입력'!$C$6*COS(B25)-'1.설계입력'!$C$7*COS(B25+C25)-'1.설계입력'!$C$8*COS('1.설계입력'!$C$15*B25) -> 79.199844 | E25: =-'1.설계입력'!$C$6*SIN(B25)+'1.설계입력'!$C$7*SIN(B25+C25)+'1.설계입력'!$C$8*SIN('1.설계입력'!$C$15*B25) -> -5.3954698 | F25: =ATAN2(('1.설계입력'!$C$6+'1.설계입력'!$C$33)/('1.설계입력'!$C$8*'1.설계입력'!$C$15)-COS((1-'1.설계입력'!$C$15)*B25),SIN((1-'1.설계입력'!$C$15)*B25)) -> -0.23340836 | G25: =('1.설계입력'!$C$6+'1.설계입력'!$C$33)*COS(B25)-('1.설계입력'!$C$7+'1.설계입력'!$C$34)*COS(B25+F25)-'1.설계입력'!$C$8*COS('1.설계입력'!$C$15*B25) -> 79.188767 | H25: =-('1.설계입력'!$C$6+'1.설계입력'!$C$33)*SIN(B25)+('1.설계입력'!$C$7+'1.설계입력'!$C$34)*SIN(B25+F25)+'1.설계입력'!$C$8*SIN('1.설계입력'!$C$15*B25) -> -5.3966321 | I25: =SQRT(D25^2+E25^2) -> 79.383414 | J25: =SQRT(G25^2+H25^2) -> 79.372441 | K25: =IF(OR(A25>180,'1.설계입력'!$C$39>=1),"",'1.설계입력'!$C$34*(1-SIN(B25)/SQRT(1+'1.설계입력'!$C$39^2-2*'1.설계입력'!$C$39*COS(B25)))-'1.설계입력'!$C$33*(1-'1.설계입력'!$C$39*COS(B25)-SQRT(MAX(0,1-'1.설계입력'!$C$39^2))*SIN(B25))/SQRT(1+'1.설계입력'!$C$39^2-2*'1.설계입력'!$C$39*COS(B25))) -> 0.0086826416
A26: =A25+'1.설계입력'!$C$12 -> 4 | B26: =RADIANS(A26) -> 0.06981317 | C26: =ATAN2('1.설계입력'!$C$6/('1.설계입력'!$C$8*'1.설계입력'!$C$15)-COS((1-'1.설계입력'!$C$15)*B26),SIN((1-'1.설계입력'!$C$15)*B26)) -> -0.17652011 | D26: ='1.설계입력'!$C$6*COS(B26)-'1.설계입력'!$C$7*COS(B26+C26)-'1.설계입력'!$C$8*COS('1.설계입력'!$C$15*B26) -> 79.232542 | E26: =-'1.설계입력'!$C$6*SIN(B26)+'1.설계입력'!$C$7*SIN(B26+C26)+'1.설계입력'!$C$8*SIN('1.설계입력'!$C$15*B26) -> -5.6330188 | F26: =ATAN2(('1.설계입력'!$C$6+'1.설계입력'!$C$33)/('1.설계입력'!$C$8*'1.설계입력'!$C$15)-COS((1-'1.설계입력'!$C$15)*B26),SIN((1-'1.설계입력'!$C$15)*B26)) -> -0.17652403 | G26: =('1.설계입력'!$C$6+'1.설계입력'!$C$33)*COS(B26)-('1.설계입력'!$C$7+'1.설계입력'!$C$34)*COS(B26+F26)-'1.설계입력'!$C$8*COS('1.설계입력'!$C$15*B26) -> 79.221397 | H26: =-('1.설계입력'!$C$6+'1.설계입력'!$C$33)*SIN(B26)+('1.설계입력'!$C$7+'1.설계입력'!$C$34)*SIN(B26+F26)+'1.설계입력'!$C$8*SIN('1.설계입력'!$C$15*B26) -> -5.6336809 | I26: =SQRT(D26^2+E26^2) -> 79.432529 | J26: =SQRT(G26^2+H26^2) -> 79.421459 | K26: =IF(OR(A26>180,'1.설계입력'!$C$39>=1),"",'1.설계입력'!$C$34*(1-SIN(B26)/SQRT(1+'1.설계입력'!$C$39^2-2*'1.설계입력'!$C$39*COS(B26)))-'1.설계입력'!$C$33*(1-'1.설계입력'!$C$39*COS(B26)-SQRT(MAX(0,1-'1.설계입력'!$C$39^2))*SIN(B26))/SQRT(1+'1.설계입력'!$C$39^2-2*'1.설계입력'!$C$39*COS(B26))) -> 0.0085538437
A27: =A26+'1.설계입력'!$C$12 -> 4.2 | B27: =RADIANS(A27) -> 0.073303829 | C27: =ATAN2('1.설계입력'!$C$6/('1.설계입력'!$C$8*'1.설계입력'!$C$15)-COS((1-'1.설계입력'!$C$15)*B27),SIN((1-'1.설계입력'!$C$15)*B27)) -> -0.1193255 | D27: ='1.설계입력'!$C$6*COS(B27)-'1.설계입력'!$C$7*COS(B27+C27)-'1.설계입력'!$C$8*COS('1.설계입력'!$C$15*B27) -> 79.251244 | E27: =-'1.설계입력'!$C$6*SIN(B27)+'1.설계입력'!$C$7*SIN(B27+C27)+'1.설계입력'!$C$8*SIN('1.설계입력'!$C$15*B27) -> -5.8776863 | F27: =ATAN2(('1.설계입력'!$C$6+'1.설계입력'!$C$33)/('1.설계입력'!$C$8*'1.설계입력'!$C$15)-COS((1-'1.설계입력'!$C$15)*B27),SIN((1-'1.설계입력'!$C$15)*B27)) -> -0.11932812 | G27: =('1.설계입력'!$C$6+'1.설계입력'!$C$33)*COS(B27)-('1.설계입력'!$C$7+'1.설계입력'!$C$34)*COS(B27+F27)-'1.설계입력'!$C$8*COS('1.설계입력'!$C$15*B27) -> 79.240061 | H27: =-('1.설계입력'!$C$6+'1.설계입력'!$C$33)*SIN(B27)+('1.설계입력'!$C$7+'1.설계입력'!$C$34)*SIN(B27+F27)+'1.설계입력'!$C$8*SIN('1.설계입력'!$C$15*B27) -> -5.8778424 | I27: =SQRT(D27^2+E27^2) -> 79.468905 | J27: =SQRT(G27^2+H27^2) -> 79.457764 | K27: =IF(OR(A27>180,'1.설계입력'!$C$39>=1),"",'1.설계입력'!$C$34*(1-SIN(B27)/SQRT(1+'1.설계입력'!$C$39^2-2*'1.설계입력'!$C$39*COS(B27)))-'1.설계입력'!$C$33*(1-'1.설계입력'!$C$39*COS(B27)-SQRT(MAX(0,1-'1.설계입력'!$C$39^2))*SIN(B27))/SQRT(1+'1.설계입력'!$C$39^2-2*'1.설계입력'!$C$39*COS(B27))) -> 0.0084257326
A28: =A27+'1.설계입력'!$C$12 -> 4.4 | B28: =RADIANS(A28) -> 0.076794487 | C28: =ATAN2('1.설계입력'!$C$6/('1.설계입력'!$C$8*'1.설계입력'!$C$15)-COS((1-'1.설계입력'!$C$15)*B28),SIN((1-'1.설계입력'!$C$15)*B28)) -> -0.061927002 | D28: ='1.설계입력'!$C$6*COS(B28)-'1.설계입력'!$C$7*COS(B28+C28)-'1.설계입력'!$C$8*COS('1.설계입력'!$C$15*B28) -> 79.255114 | E28: =-'1.설계입력'!$C$6*SIN(B28)+'1.설계입력'!$C$7*SIN(B28+C28)+'1.설계입력'!$C$8*SIN('1.설계입력'!$C$15*B28) -> -6.1268578 | F28: =ATAN2(('1.설계입력'!$C$6+'1.설계입력'!$C$33)/('1.설계입력'!$C$8*'1.설계입력'!$C$15)-COS((1-'1.설계입력'!$C$15)*B28),SIN((1-'1.설계입력'!$C$15)*B28)) -> -0.061928357 | G28: =('1.설계입력'!$C$6+'1.설계입력'!$C$33)*COS(B28)-('1.설계입력'!$C$7+'1.설계입력'!$C$34)*COS(B28+F28)-'1.설계입력'!$C$8*COS('1.설계입력'!$C$15*B28) -> 79.243924 | H28: =-('1.설계입력'!$C$6+'1.설계입력'!$C$33)*SIN(B28)+('1.설계입력'!$C$7+'1.설계입력'!$C$34)*SIN(B28+F28)+'1.설계입력'!$C$8*SIN('1.설계입력'!$C$15*B28) -> -6.126505 | I28: =SQRT(D28^2+E28^2) -> 79.491581 | J28: =SQRT(G28^2+H28^2) -> 79.480397 | K28: =IF(OR(A28>180,'1.설계입력'!$C$39>=1),"",'1.설계입력'!$C$34*(1-SIN(B28)/SQRT(1+'1.설계입력'!$C$39^2-2*'1.설계입력'!$C$39*COS(B28)))-'1.설계입력'!$C$33*(1-'1.설계입력'!$C$39*COS(B28)-SQRT(MAX(0,1-'1.설계입력'!$C$39^2))*SIN(B28))/SQRT(1+'1.설계입력'!$C$39^2-2*'1.설계입력'!$C$39*COS(B28))) -> 0.0082983482
A29: =A28+'1.설계입력'!$C$12 -> 4.6 | B29: =RADIANS(A29) -> 0.080285146 | C29: =ATAN2('1.설계입력'!$C$6/('1.설계입력'!$C$8*'1.설계입력'!$C$15)-COS((1-'1.설계입력'!$C$15)*B29),SIN((1-'1.설계입력'!$C$15)*B29)) -> -0.0044247711 | D29: ='1.설계입력'!$C$6*COS(B29)-'1.설계입력'!$C$7*COS(B29+C29)-'1.설계입력'!$C$8*COS('1.설계입력'!$C$15*B29) -> 79.243718 | E29: =-'1.설계입력'!$C$6*SIN(B29)+'1.설계입력'!$C$7*SIN(B29+C29)+'1.설계입력'!$C$8*SIN('1.설계입력'!$C$15*B29) -> -6.377796 | F29: =ATAN2(('1.설계입력'!$C$6+'1.설계입력'!$C$33)/('1.설계입력'!$C$8*'1.설계입력'!$C$15)-COS((1-'1.설계입력'!$C$15)*B29),SIN((1-'1.설계입력'!$C$15)*B29)) -> -0.0044248678 | G29: =('1.설계입력'!$C$6+'1.설계입력'!$C$33)*COS(B29)-('1.설계입력'!$C$7+'1.설계입력'!$C$34)*COS(B29+F29)-'1.설계입력'!$C$8*COS('1.설계입력'!$C$15*B29) -> 79.232551 | H29: =-('1.설계입력'!$C$6+'1.설계입력'!$C$33)*SIN(B29)+('1.설계입력'!$C$7+'1.설계입력'!$C$34)*SIN(B29+F29)+'1.설계입력'!$C$8*SIN('1.설계입력'!$C$15*B29) -> -6.3769339 | I29: =SQRT(D29^2+E29^2) -> 79.499957 | J29: =SQRT(G29^2+H29^2) -> 79.488757 | K29: =IF(OR(A29>180,'1.설계입력'!$C$39>=1),"",'1.설계입력'!$C$34*(1-SIN(B29)/SQRT(1+'1.설계입력'!$C$39^2-2*'1.설계입력'!$C$39*COS(B29)))-'1.설계입력'!$C$33*(1-'1.설계입력'!$C$39*COS(B29)-SQRT(MAX(0,1-'1.설계입력'!$C$39^2))*SIN(B29))/SQRT(1+'1.설계입력'!$C$39^2-2*'1.설계입력'!$C$39*COS(B29))) -> 0.0081717288
A30: =A29+'1.설계입력'!$C$12 -> 4.8 | B30: =RADIANS(A30) -> 0.083775804 | C30: =ATAN2('1.설계입력'!$C$6/('1.설계입력'!$C$8*'1.설계입력'!$C$15)-COS((1-'1.설계입력'!$C$15)*B30),SIN((1-'1.설계입력'!$C$15)*B30)) -> 0.053084819 | D30: ='1.설계입력'!$C$6*COS(B30)-'1.설계입력'!$C$7*COS(B30+C30)-'1.설계입력'!$C$8*COS('1.설계입력'!$C$15*B30) -> 79.217039 | E30: =-'1.설계입력'!$C$6*SIN(B30)+'1.설계입력'!$C$7*SIN(B30+C30)+'1.설계입력'!$C$8*SIN('1.설계입력'!$C$15*B30) -> -6.6277156 | F30: =ATAN2(('1.설계입력'!$C$6+'1.설계입력'!$C$33)/('1.설계입력'!$C$8*'1.설계입력'!$C$15)-COS((1-'1.설계입력'!$C$15)*B30),SIN((1-'1.설계입력'!$C$15)*B30)) -> 0.05308598 | G30: =('1.설계입력'!$C$6+'1.설계입력'!$C$33)*COS(B30)-('1.설계입력'!$C$7+'1.설계입력'!$C$34)*COS(B30+F30)-'1.설계입력'!$C$8*COS('1.설계입력'!$C$15*B30) -> 79.205926 | H30: =-('1.설계입력'!$C$6+'1.설계입력'!$C$33)*SIN(B30)+('1.설계입력'!$C$7+'1.설계입력'!$C$34)*SIN(B30+F30)+'1.설계입력'!$C$8*SIN('1.설계입력'!$C$15*B30) -> -6.6263465 | I30: =SQRT(D30^2+E30^2) -> 79.49381 | J30: =SQRT(G30^2+H30^2) -> 79.482622 | K30: =IF(OR(A30>180,'1.설계입력'!$C$39>=1),"",'1.설계입력'!$C$34*(1-SIN(B30)/SQRT(1+'1.설계입력'!$C$39^2-2*'1.설계입력'!$C$39*COS(B30)))-'1.설계입력'!$C$33*(1-'1.설계입력'!$C$39*COS(B30)-SQRT(MAX(0,1-'1.설계입력'!$C$39^2))*SIN(B30))/SQRT(1+'1.설계입력'!$C$39^2-2*'1.설계입력'!$C$39*COS(B30))) -> 0.0080459114
A31: =A30+'1.설계입력'!$C$12 -> 5 | B31: =RADIANS(A31) -> 0.087266463 | C31: =ATAN2('1.설계입력'!$C$6/('1.설계입력'!$C$8*'1.설계입력'!$C$15)-COS((1-'1.설계입력'!$C$15)*B31),SIN((1-'1.설계입력'!$C$15)*B31)) -> 0.11050566 | D31: ='1.설계입력'!$C$6*COS(B31)-'1.설계입력'!$C$7*COS(B31+C31)-'1.설계입력'!$C$8*COS('1.설계입력'!$C$15*B31) -> 79.175477 | E31: =-'1.설계입력'!$C$6*SIN(B31)+'1.설계입력'!$C$7*SIN(B31+C31)+'1.설계입력'!$C$8*SIN('1.설계입력'!$C$15*B31) -> -6.8738597 | F31: =ATAN2(('1.설계입력'!$C$6+'1.설계입력'!$C$33)/('1.설계입력'!$C$8*'1.설계입력'!$C$15)-COS((1-'1.설계입력'!$C$15)*B31),SIN((1-'1.설계입력'!$C$15)*B31)) -> 0.11050808 | G31: =('1.설계입력'!$C$6+'1.설계입력'!$C$33)*COS(B31)-('1.설계입력'!$C$7+'1.설계입력'!$C$34)*COS(B31+F31)-'1.설계입력'!$C$8*COS('1.설계입력'!$C$15*B31) -> 79.164449 | H31: =-('1.설계입력'!$C$6+'1.설계입력'!$C$33)*SIN(B31)+('1.설계입력'!$C$7+'1.설계입력'!$C$34)*SIN(B31+F31)+'1.설계입력'!$C$8*SIN('1.설계입력'!$C$15*B31) -> -6.8719884 | I31: =SQRT(D31^2+E31^2) -> 79.473304 | J31: =SQRT(G31^2+H31^2) -> 79.462156 | K31: =IF(OR(A31>180,'1.설계입력'!$C$39>=1),"",'1.설계입력'!$C$34*(1-SIN(B31)/SQRT(1+'1.설계입력'!$C$39^2-2*'1.설계입력'!$C$39*COS(B31)))-'1.설계입력'!$C$33*(1-'1.설계입력'!$C$39*COS(B31)-SQRT(MAX(0,1-'1.설계입력'!$C$39^2))*SIN(B31))/SQRT(1+'1.설계입력'!$C$39^2-2*'1.설계입력'!$C$39*COS(B31))) -> 0.0079209317
A32: =A31+'1.설계입력'!$C$12 -> 5.2 | B32: =RADIANS(A32) -> 0.090757121 | C32: =ATAN2('1.설계입력'!$C$6/('1.설계입력'!$C$8*'1.설계입력'!$C$15)-COS((1-'1.설계입력'!$C$15)*B32),SIN((1-'1.설계입력'!$C$15)*B32)) -> 0.16773841 | D32: ='1.설계입력'!$C$6*COS(B32)-'1.설계입력'!$C$7*COS(B32+C32)-'1.설계입력'!$C$8*COS('1.설계입력'!$C$15*B32) -> 79.119839 | E32: =-'1.설계입력'!$C$6*SIN(B32)+'1.설계입력'!$C$7*SIN(B32+C32)+'1.설계입력'!$C$8*SIN('1.설계입력'!$C$15*B32) -> -7.1135735 | F32: =ATAN2(('1.설계입력'!$C$6+'1.설계입력'!$C$33)/('1.설계입력'!$C$8*'1.설계입력'!$C$15)-COS((1-'1.설계입력'!$C$15)*B32),SIN((1-'1.설계입력'!$C$15)*B32)) -> 0.16774212 | G32: =('1.설계입력'!$C$6+'1.설계입력'!$C$33)*COS(B32)-('1.설계입력'!$C$7+'1.설계입력'!$C$34)*COS(B32+F32)-'1.설계입력'!$C$8*COS('1.설계입력'!$C$15*B32) -> 79.108925 | H32: =-('1.설계입력'!$C$6+'1.설계입력'!$C$33)*SIN(B32)+('1.설계입력'!$C$7+'1.설계입력'!$C$34)*SIN(B32+F32)+'1.설계입력'!$C$8*SIN('1.설계입력'!$C$15*B32) -> -7.1112076 | I32: =SQRT(D32^2+E32^2) -> 79.438982 | J32: =SQRT(G32^2+H32^2) -> 79.4279 | K32: =IF(OR(A32>180,'1.설계입력'!$C$39>=1),"",'1.설계입력'!$C$34*(1-SIN(B32)/SQRT(1+'1.설계입력'!$C$39^2-2*'1.설계입력'!$C$39*COS(B32)))-'1.설계입력'!$C$33*(1-'1.설계입력'!$C$39*COS(B32)-SQRT(MAX(0,1-'1.설계입력'!$C$39^2))*SIN(B32))/SQRT(1+'1.설계입력'!$C$39^2-2*'1.설계입력'!$C$39*COS(B32))) -> 0.0077968239
A33: =A32+'1.설계입력'!$C$12 -> 5.4 | B33: =RADIANS(A33) -> 0.09424778 | C33: =ATAN2('1.설계입력'!$C$6/('1.설계입력'!$C$8*'1.설계입력'!$C$15)-COS((1-'1.설계입력'!$C$15)*B33),SIN((1-'1.설계입력'!$C$15)*B33)) -> 0.22467679 | D33: ='1.설계입력'!$C$6*COS(B33)-'1.설계입력'!$C$7*COS(B33+C33)-'1.설계입력'!$C$8*COS('1.설계입력'!$C$15*B33) -> 79.051314 | E33: =-'1.설계입력'!$C$6*SIN(B33)+'1.설계입력'!$C$7*SIN(B33+C33)+'1.설계입력'!$C$8*SIN('1.설계입력'!$C$15*B33) -> -7.3443774 | F33: =ATAN2(('1.설계입력'!$C$6+'1.설계입력'!$C$33)/('1.설계입력'!$C$8*'1.설계입력'!$C$15)-COS((1-'1.설계입력'!$C$15)*B33),SIN((1-'1.설계입력'!$C$15)*B33)) -> 0.22468183 | G33: =('1.설계입력'!$C$6+'1.설계입력'!$C$33)*COS(B33)-('1.설계입력'!$C$7+'1.설계입력'!$C$34)*COS(B33+F33)-'1.설계입력'!$C$8*COS('1.설계입력'!$C$15*B33) -> 79.040542 | H33: =-('1.설계입력'!$C$6+'1.설계입력'!$C$33)*SIN(B33)+('1.설계입력'!$C$7+'1.설계입력'!$C$34)*SIN(B33+F33)+'1.설계입력'!$C$8*SIN('1.설계입력'!$C$15*B33) -> -7.3415268 | I33: =SQRT(D33^2+E33^2) -> 79.391751 | J33: =SQRT(G33^2+H33^2) -> 79.380762 | K33: =IF(OR(A33>180,'1.설계입력'!$C$39>=1),"",'1.설계입력'!$C$34*(1-SIN(B33)/SQRT(1+'1.설계입력'!$C$39^2-2*'1.설계입력'!$C$39*COS(B33)))-'1.설계입력'!$C$33*(1-'1.설계입력'!$C$39*COS(B33)-SQRT(MAX(0,1-'1.설계입력'!$C$39^2))*SIN(B33))/SQRT(1+'1.설계입력'!$C$39^2-2*'1.설계입력'!$C$39*COS(B33))) -> 0.007673621
A34: =A33+'1.설계입력'!$C$12 -> 5.6 | B34: =RADIANS(A34) -> 0.097738438 | C34: =ATAN2('1.설계입력'!$C$6/('1.설계입력'!$C$8*'1.설계입력'!$C$15)-COS((1-'1.설계입력'!$C$15)*B34),SIN((1-'1.설계입력'!$C$15)*B34)) -> 0.28120329 | D34: ='1.설계입력'!$C$6*COS(B34)-'1.설계입력'!$C$7*COS(B34+C34)-'1.설계입력'!$C$8*COS('1.설계입력'!$C$15*B34) -> 78.97143 | E34: =-'1.설계입력'!$C$6*SIN(B34)+'1.설계입력'!$C$7*SIN(B34+C34)+'1.설계입력'!$C$8*SIN('1.설계입력'!$C$15*B34) -> -7.5640354 | F34: =ATAN2(('1.설계입력'!$C$6+'1.설계입력'!$C$33)/('1.설계입력'!$C$8*'1.설계입력'!$C$15)-COS((1-'1.설계입력'!$C$15)*B34),SIN((1-'1.설계입력'!$C$15)*B34)) -> 0.28120969 | G34: =('1.설계입력'!$C$6+'1.설계입력'!$C$33)*COS(B34)-('1.설계입력'!$C$7+'1.설계입력'!$C$34)*COS(B34+F34)-'1.설계입력'!$C$8*COS('1.설계입력'!$C$15*B34) -> 78.960829 | H34: =-('1.설계입력'!$C$6+'1.설계입력'!$C$33)*SIN(B34)+('1.설계입력'!$C$7+'1.설계입력'!$C$34)*SIN(B34+F34)+'1.설계입력'!$C$8*SIN('1.설계입력'!$C$15*B34) -> -7.5607126 | I34: =SQRT(D34^2+E34^2) -> 79.332852 | J34: =SQRT(G34^2+H34^2) -> 79.321982 | K34: =IF(OR(A34>180,'1.설계입력'!$C$39>=1),"",'1.설계입력'!$C$34*(1-SIN(B34)/SQRT(1+'1.설계입력'!$C$39^2-2*'1.설계입력'!$C$39*COS(B34)))-'1.설계입력'!$C$33*(1-'1.설계입력'!$C$39*COS(B34)-SQRT(MAX(0,1-'1.설계입력'!$C$39^2))*SIN(B34))/SQRT(1+'1.설계입력'!$C$39^2-2*'1.설계입력'!$C$39*COS(B34))) -> 0.0075513542
... A1805: =A1804+'1.설계입력'!$C$12 -> 359.8 | B1805: =RADIANS(A1805) -> 6.2796946 | C1805: =ATAN2('1.설계입력'!$C$6/('1.설계입력'!$C$8*'1.설계입력'!$C$15)-COS((1-'1.설계입력'!$C$15)*B1805),SIN((1-'1.설계입력'!$C$15)*B1805)) -> 0.34646146 | D1805: ='1.설계입력'!$C$6*COS(B1805)-'1.설계입력'!$C$7*COS(B1805+C1805)-'1.설계입력'!$C$8*COS('1.설계입력'!$C$15*B1805) -> 76.747059 | E1805: =-'1.설계입력'!$C$6*SIN(B1805)+'1.설계입력'!$C$7*SIN(B1805+C1805)+'1.설계입력'!$C$8*SIN('1.설계입력'!$C$15*B1805) -> 1.4226192 | F1805: =ATAN2(('1.설계입력'!$C$6+'1.설계입력'!$C$33)/('1.설계입력'!$C$8*'1.설계입력'!$C$15)-COS((1-'1.설계입력'!$C$15)*B1805),SIN((1-'1.설계입력'!$C$15)*B1805)) -> 0.34650536 | G1805: =('1.설계입력'!$C$6+'1.설계입력'!$C$33)*COS(B1805)-('1.설계입력'!$C$7+'1.설계입력'!$C$34)*COS(B1805+F1805)-'1.설계입력'!$C$8*COS('1.설계입력'!$C$15*B1805) -> 76.73639 | H1805: =-('1.설계입력'!$C$6+'1.설계입력'!$C$33)*SIN(B1805)+('1.설계입력'!$C$7+'1.설계입력'!$C$34)*SIN(B1805+F1805)+'1.설계입력'!$C$8*SIN('1.설계입력'!$C$15*B1805) -> 1.425498 | I1805: =SQRT(D1805^2+E1805^2) -> 76.760243 | J1805: =SQRT(G1805^2+H1805^2) -> 76.749629 | K1805: =IF(OR(A1805>180,'1.설계입력'!$C$39>=1),"",'1.설계입력'!$C$34*(1-SIN(B1805)/SQRT(1+'1.설계입력'!$C$39^2-2*'1.설계입력'!$C$39*COS(B1805)))-'1.설계입력'!$C$33*(1-'1.설계입력'!$C$39*COS(B1805)-SQRT(MAX(0,1-'1.설계입력'!$C$39^2))*SIN(B1805))/SQRT(1+'1.설계입력'!$C$39^2-2*'1.설계입력'!$C$39*COS(B1805)))

Sheet 3.치형그래프
A1: 치형 곡선 (논문 A Fig.6 대응)
A2: 파라미터를 바꾸면 이 그래프가 자동으로 갱신됩니다. 꽃잎 개수를 세어 z_c 와 같은지 확인하세요.
A3: 두 곡선은 수 um 차이라 이 배율에서는 겹쳐 보입니다. 차이는 아래 '초기 틈새' 그래프로 확인하세요.

Sheet 4.CAD출력
A1: CAD 가져오기용 좌표
A2: B·C 열을 복사해 CAD 스플라인으로 붙이거나, 이 시트를 CSV로 저장해 가져오세요. D열은 CSV 한 줄 형태입니다.
A4: 치형 선택 | B4: 수정 | C4: =IF(B4="표준","논문 A 식(1)(2) 결과","논문 B 식(4)(5) 결과 - 제작용") -> 논문 B 식(4)(5) 결과 - 제작용
A6: 점 번호 | B6: X [mm] | C6: Y [mm] | D6: CSV (X,Y)
A7: 1 | B7: =IF($B$4="표준",'2.치형좌표'!D6,'2.치형좌표'!G6) -> 76.4888 | C7: =IF($B$4="표준",'2.치형좌표'!E6,'2.치형좌표'!H6) -> 0 | D7: =TEXT(B7,"0.00000")&","&TEXT(C7,"0.00000") -> 76.48880,0.00000
A8: 2 | B8: =IF($B$4="표준",'2.치형좌표'!D7,'2.치형좌표'!G7) -> 76.73639 | C8: =IF($B$4="표준",'2.치형좌표'!E7,'2.치형좌표'!H7) -> -1.425498 | D8: =TEXT(B8,"0.00000")&","&TEXT(C8,"0.00000") -> 76.73639,-1.42550
A9: 3 | B9: =IF($B$4="표준",'2.치형좌표'!D8,'2.치형좌표'!G8) -> 77.202445 | C9: =IF($B$4="표준",'2.치형좌표'!E8,'2.치형좌표'!H8) -> -2.3586646 | D9: =TEXT(B9,"0.00000")&","&TEXT(C9,"0.00000") -> 77.20245,-2.35866
A10: 4 | B10: =IF($B$4="표준",'2.치형좌표'!D9,'2.치형좌표'!G9) -> 77.592647 | C10: =IF($B$4="표준",'2.치형좌표'!E9,'2.치형좌표'!H9) -> -2.8729283 | D10: =TEXT(B10,"0.00000")&","&TEXT(C10,"0.00000") -> 77.59265,-2.87293
A11: 5 | B11: =IF($B$4="표준",'2.치형좌표'!D10,'2.치형좌표'!G10) -> 77.861844 | C11: =IF($B$4="표준",'2.치형좌표'!E10,'2.치형좌표'!H10) -> -3.1631405 | D11: =TEXT(B11,"0.00000")&","&TEXT(C11,"0.00000") -> 77.86184,-3.16314
A12: 6 | B12: =IF($B$4="표준",'2.치형좌표'!D11,'2.치형좌표'!G11) -> 78.044689 | C12: =IF($B$4="표준",'2.치형좌표'!E11,'2.치형좌표'!H11) -> -3.3438574 | D12: =TEXT(B12,"0.00000")&","&TEXT(C12,"0.00000") -> 78.04469,-3.34386
A13: 7 | B13: =IF($B$4="표준",'2.치형좌표'!D12,'2.치형좌표'!G12) -> 78.176089 | C13: =IF($B$4="표준",'2.치형좌표'!E12,'2.치형좌표'!H12) -> -3.4712463 | D13: =TEXT(B13,"0.00000")&","&TEXT(C13,"0.00000") -> 78.17609,-3.47125
A14: 8 | B14: =IF($B$4="표준",'2.치형좌표'!D13,'2.치형좌표'!G13) -> 78.279451 | C14: =IF($B$4="표준",'2.치형좌표'!E13,'2.치형좌표'!H13) -> -3.5737908 | D14: =TEXT(B14,"0.00000")&","&TEXT(C14,"0.00000") -> 78.27945,-3.57379
A15: 9 | B15: =IF($B$4="표준",'2.치형좌표'!D14,'2.치형좌표'!G14) -> 78.368985 | C15: =IF($B$4="표준",'2.치형좌표'!E14,'2.치형좌표'!H14) -> -3.6672348 | D15: =TEXT(B15,"0.00000")&","&TEXT(C15,"0.00000") -> 78.36899,-3.66723
A16: 10 | B16: =IF($B$4="표준",'2.치형좌표'!D15,'2.치형좌표'!G15) -> 78.45286 | C16: =IF($B$4="표준",'2.치형좌표'!E15,'2.치형좌표'!H15) -> -3.7610756 | D16: =TEXT(B16,"0.00000")&","&TEXT(C16,"0.00000") -> 78.45286,-3.76108
A17: 11 | B17: =IF($B$4="표준",'2.치형좌표'!D16,'2.치형좌표'!G16) -> 78.535396 | C17: =IF($B$4="표준",'2.치형좌표'!E16,'2.치형좌표'!H16) -> -3.861443 | D17: =TEXT(B17,"0.00000")&","&TEXT(C17,"0.00000") -> 78.53540,-3.86144
A18: 12 | B18: =IF($B$4="표준",'2.치형좌표'!D17,'2.치형좌표'!G17) -> 78.618441 | C18: =IF($B$4="표준",'2.치형좌표'!E17,'2.치형좌표'!H17) -> -3.9724406 | D18: =TEXT(B18,"0.00000")&","&TEXT(C18,"0.00000") -> 78.61844,-3.97244
... A1806: 1800 | B1806: =IF($B$4="표준",'2.치형좌표'!D1805,'2.치형좌표'!G1805) -> 76.73639 | C1806: =IF($B$4="표준",'2.치형좌표'!E1805,'2.치형좌표'!H1805) -> 1.425498 | D1806: =TEXT(B1806,"0.00000")&","&TEXT(C1806,"0.00000") -> 76.73639,1.42550

Sheet 5.사용설명
B2: 사용 설명 및 근거
B4: 1. 이 파일은 무엇인가
B5: 출처 논문 A | C5: Nachimowicz, J. & Rafalowski, S. (2016) Modelling the Meshing of Cycloidal Gears, Acta Mechanica et Automatica 10(2), 137-140. DOI 10.1515/ama-2016-0022
B6: 출처 논문 B | C6: Song, X., Chen, Y. & Yang, J. (2023) Study of the Transmission Characteristics of the Cycloid Gear Based on a Multi-Objective Optimization Modification, Machines 11, 775. DOI 10.3390/machines11080775
B7: 치형 방정식 원출처 | C7: Shin, J. & Kwon, S. (2006) On the lobe profile design in a cycloid reducer using instant velocity center, Mechanism and Machine Theory 41(5).
B8: 2. 사용 순서
B9: 1단계 | C9: [1.설계입력] 노란 셀에 파라미터를 넣습니다. r_p, r_rp, a, z_c 가 핵심입니다.
B10: 2단계 | C10: 같은 시트 '설계 조건 검증' 블록이 모두 초록(통과)인지 확인합니다. 빨강(위반)이면 그 치형은 물리적으로 제작할 수 없습니다.
B11: 3단계 | C11: [2.치형좌표] 가 자동 갱신됩니다. 오른쪽 '치형 검증' 블록이 통과인지 봅니다.
B12: 4단계 | C12: [3.치형그래프] 에서 꽃잎 개수를 세어 z_c 와 같은지 확인합니다. 다르면 어딘가 잘못된 것입니다.
B13: 5단계 | C13: [1.설계입력] '치형 수정 계수' 에 d_rp(음수), d_rrp(양수)를 넣습니다. 합이 dr 과 같아야 합니다(자동 검증).
B14: 6단계 | C14: [4.CAD출력] 에서 '수정' 을 선택하고 X·Y 열을 복사해 CAD로 가져갑니다.
B15: 3. 핵심 수식과 근거
B16: 표준 치형 (논문A 식1) | C16: Bx = r_p*cos(phi) - r_rp*cos(phi+Psi) - a*cos(z_p*phi) By = -r_p*sin(phi) + r_rp*sin(phi+Psi) + a*sin(z_p*phi) 첫 항 = 기본 원, 둘째 항 = 핀 반경 오프셋, 셋째 항 = 꽃잎 물결(진폭 a, z_p회 진동)
B17: 접촉각 (논문A 식2) | C17: Psi = atan[ sin((1-z_p)*phi) / ( r_p/(a*z_p) - cos((1-z_p)*phi) ) ] 이 파일은 ATAN 대신 ATAN2(분모, 분자)를 씁니다. Excel 인수 순서는 (x, y) 입니다.
B18: S (논문B 식3) | C18: S = 1 + K1^2 - 2*K1*cos(phi) 코사인 법칙 형태. sqrt(S)가 거리이고 r_rp/S 항이 핀 반경 오프셋 역할을 합니다.
B19: 수정 치형 (구현 방식) | C19: 논문 B 식(4)(5)를 그대로 쓰지 않고, 검증된 논문 A 식(1)에 다음 치환을 적용했습니다. r_p -> r_p + d_rp, r_rp -> r_rp + d_rrp 이유는 아래 '6. 논문 B 식을 그대로 쓰지 않은 이유' 를 보세요. 이 방식의 결과는 논문 B 식(20) 초기틈새와 독립적으로 교차검증했습니다.
B20: 초기 틈새 (논문B 식20) | C20: d(phi) = d_rrp*(1 - sin(phi)/sqrt(S)) - d_rp*(1 - K1*cos(phi) - sqrt(1-K1^2)*sin(phi))/sqrt(S) 출처는 Zhu(2010) 기어설계핸드북. 첫 항이 핀반경 수정의 기여, 둘째 항이 핀위치 수정의 기여입니다. 틈새는 두 수정의 선형 중첩입니다.
B21: 경험식 (논문B 식18·19) | C21: d_rrp = dr/(1-sqrt(1-K1^2)), d_rp = -dr*sqrt(1-K1^2)/(1-sqrt(1-K1^2)) Guan(2002)의 복합수정 경험식. Song 예제에서 0.0157 / -0.0107 mm.
B22: 4. 구동 성립 조건이 왜 중요한가
B23: 조건 | C23: r_p/(a*z_p) > 1 (같은 뜻으로 K1 < 1)
B24: 이유 | C24: Psi 식의 분모가 r_p/(a*z_p) - cos(...) 입니다. cos의 최대가 1이므로 r_p/(a*z_p) <= 1 이면 어떤 phi에서 분모가 0이 되어 Psi가 발산합니다. 기하학적으로는 편심이 너무 커서 꽃잎이 자기 자신을 파고드는 상태입니다.
B25: 부수 효과 | C25: 이 조건이 성립하면 분모가 항상 양수이므로 ATAN 과 ATAN2 결과가 같습니다. 조건 경계를 탐색할 때만 ATAN2 가 안전합니다.
B26: 5. 논문을 그대로 쓰지 않고 고친 점
B27: 하드코딩 제거 | C27: 논문 A 스프레드시트는 수식에 43.64, 12, -11, 1.818 을 직접 박아 넣었습니다. 파라미터를 바꾸면 1800행을 다시 고쳐야 합니다. 이 파일은 전부 절대참조($C$6 등)로 바꿔 입력 셀만 고치면 즉시 반영됩니다.
B28: Psi 참조 오류 수정 | C28: 논문 A Tab.2 의 Excel 수식은 COS(B19+B20) 으로 되어 있어 Psi 대신 다음 행의 phi 를 더합니다. 식(1)에 따르면 COS(B19+C19) 가 맞습니다. 이 파일은 올바르게 같은 행의 Psi 를 참조합니다.
B29: 정확한 상수 사용 | C29: 논문은 r_p/(a*z_p) 를 1.818 로 반올림해 넣었습니다. 이 파일은 셀 참조로 계산하므로 반올림 오차가 없습니다.
B30: K1 갱신 | C30: 핀위치 수정이 들어가면 K1 = a*z_p/(r_p+d_rp) 로 갱신해야 합니다(논문 B 명시). [1.설계입력] C39 가 그 값이며 초기틈새 식(20) 계산에 쓰입니다.
B31: 6. 논문 B 식(4)(5)를 그대로 쓰지 않은 이유
B32: 무엇을 발견했나 | C32: 논문 B 식(4)(5)를 그대로 구현해 계산해 보면 phi=0 에서 x = 27.99mm 가 나옵니다. 같은 조건의 표준 치형은 76.5mm 이므로 48mm 나 어긋납니다. 수정량은 수 um 여야 하는데 있을 수 없는 차이입니다.
B33: 원인 | C33: 논문 B 식의 오프셋 항은 r_rp/S 형태입니다. S = 1+K1^2-2*K1*cos(phi) 이므로 phi=0 에서 S = (1-K1)^2 = 0.0719 이고, r_rp/S = 4/0.0719 = 55.6mm 가 됩니다. 핀 반경 4mm 의 14배입니다. 즉 논문 B 의 S^-1 오프셋은 논문 A 의 치형과 스케일이 맞지 않습니다. 두 논문의 phi 정의가 다른 것과 같은 뿌리의 문제입니다.
B34: 어떻게 했나 | C34: 검증된 논문 A 식(1)(2)에 r_p -> r_p+d_rp, r_rp -> r_rp+d_rrp 치환을 적용했습니다. 물리적으로도 이것이 '핀이 조금 더 굵고 조금 더 안쪽에 있다고 가정해 깎는다' 는 핀반경·핀위치 수정의 정의 그대로입니다.
B35: 교차 검증 결과 | C35: 이 방식으로 얻은 표준-수정 곡선 사이 법선 간격은 0.0104 ~ 0.0112mm 입니다. 논문 B 식(20)의 초기 틈새는 0 ~ 0.0111mm 로 최대값이 거의 일치하며, 43도에서 최소가 되는 것도 논문 B Fig.11 의 형태와 맞습니다. 서로 독립적인 두 식이 일치하므로 이 구현을 신뢰할 수 있습니다.
B36: 실무적 의미 | C36: 논문 B 식(4)(5)를 그대로 스프레드시트에 옮기면 쓸 수 없는 치형이 나옵니다. 논문 수식을 옮길 때는 반드시 스케일 검산(r_p-r_rp+-a 와 비교)을 하세요.
B37: 초기틈새는 0~180도만 유효 | C37: 식(20)에는 sin(phi) 가 들어갑니다. 180도를 넘으면 sin 이 음수가 되어 값이 부풀려집니다(0~360도 전체로 계산하면 최대 0.0204mm, 0~180도만 계산하면 0.0112mm). 논문 B Fig.11 이 0~180도만 그리는 이유입니다. 핀의 절반만 맞물림에 참여하므로 반주기만 물리적으로 의미가 있습니다. 이 파일은 K열에서 180도 초과 구간을 공백 처리했습니다. 0~180도 최대값 0.0112mm 는 표준-수정 곡선의 기하학적 법선간격 0.0112mm 와 0.1% 오차로 일치합니다(교차검증).
B38: 7. 이 파일이 하지 못하는 것
B39: 전달오차 / 백래시 | C39: 논문 B 식(15)의 비선형 연립방정식을 수치로 풀어야 하므로 Excel 로는 불가능합니다. MATLAB/Python 의 fsolve 등이 필요합니다.
B40: 접촉력 / 접촉응력 | C40: delta_max 와 F_max 가 서로를 필요로 하는 순환 의존이라 반복 계산이 필요합니다. Excel 반복계산 옵션으로 가능하지만 수렴 제어가 어려워 넣지 않았습니다.
B41: 강도 / 수명 / 효율 | C41: 별도 해석(FEM, 윤활 모델)이 필요합니다.
B42: 1단 유성기어 | C42: 이 파일은 RV 감속기의 2단(사이클로이드-핀)만 다룹니다.
...

Sheet 6.성능계산
B2: 성능 계산 결과 (파이썬 solver 출력 - 수식이 아닙니다)
B3: 계산 시각 2026-08-11 05:08:00. 1.설계입력 을 바꾼 뒤 성능계산.bat 을 다시 실행하면 이 시트가 갱신됩니다.
B5: 입력 요약
B6: 핀 중심원 반경 r_p | C6: 82 | D6: mm | E6: 1.설계입력 C6
B7: 핀 반경 r_rp | C7: 4 | D7: mm | E7: 1.설계입력 C7
B8: 편심량 a | C8: 1.5 | D8: mm | E8: 1.설계입력 C8
B9: 이빨 수 z_c | C9: 39 | D9: 개 | E9: 감속비와 동일
B10: 핀 수 z_p | C10: 40 | D10: 개 | E10: z_c + 1
B11: 기어 폭 b_c | C11: 15 | D11: mm | E11: 접촉 길이
B12: 출력 토크 T | C12: 420 | D12: N.m | E12: 1.설계입력 C42
B13: 핀위치 수정 d_rp | C13: -0.0031 | D13: mm | E13: 1.설계입력 C33
B14: 핀반경 수정 d_rrp | C14: 0.0081 | D14: mm | E14: 1.설계입력 C34
B15: K1 (수정 후) | C15: 0.73173498 | D15: - | E15: a*z_p/(r_p+d_rp). 논문 B 명시대로 갱신한 값
B17: 접촉력 (논문 B 식20~32)
B18: 최대 접촉력 F_max | C18: 583.4609 | D18: N | E18: 가장 큰 힘을 받는 이빨의 접촉력
B19: 최대 변형 delta_max | C19: 2.8253197 | D19: um | E19: 헤르츠 접촉 변형. 초기 틈새와 같은 자릿수여야 정상
B20: 동시 접촉 이빨 수 | C20: 8 | D20: 개 | E20: 핀 2~9 번
B21: 맞물림 각 범위 | C21: 18 | D21: deg | E21: 18.0 ~ 81.0 deg (논문 B Fig.11 대응)
B22: 최대 초기 틈새 | C22: 11.2 | D22: um | E22: 논문 B 식(20)
B23: 식(27) 잔차 | C23: 4.6663387e-12 | D23: % | E23: 0 에 가까우면 변형-힘 두 식이 일관됨
B25: 백래시 / 전달오차 (논문 B 식15·16)
B26: 진입각 beta | C26: 0.61653648 | D26: arcmin | E26: 틈새를 극복하고 접촉하기까지 도는 각
B27: 백래시 (2*beta) | C27: 1.233073 | D27: arcmin | E27: 논문 B 3.5절 정의
B28: 전달오차 평균 | C28: 0.60094122 | D28: arcmin | E28: 무부하, 한 주기 평균
B29: 전달오차 최소 | C29: 0.60016659 | D29: arcmin | E29: 절댓값이 작을수록 정밀
B30: 전달오차 최대 | C30: 0.60235028 | D30: arcmin
B31: 전달오차 변동폭 | C31: 0.0021836898 | D31: arcmin | E31: 이 변동이 진동·소음의 가진 성분
B32: 표준치형 TE 검증 | C32: 4.1108304e-05 | D32: arcmin | E32: 공액 치형이므로 0 이어야 정상. 0.05 미만이면 solver 정상
B34: 백래시 (1m 팔 끝단) | C34: 0.35868639 | D34: mm | E34: 길이 1m 로봇 팔 끝에서의 변위. 1 arcmin = 0.29 mm
G36: 핀별 접촉력
G37: 핀 번호 | H37: 각도 deg | I37: 접촉력 N | J37: 초기틈새 um | K37: 변형 um
G38: 1 | H38: 9 | I38: 0 | J38: 5.6394305 | K38: 1.47339
G39: 2 | H39: 18 | I39: 9.2668054 | J39: 2.2591279 | K39: 2.304001
G40: 3 | H40: 27 | I40: 404.90415 | J40: 0.70532838 | K40: 2.6660145
G41: 4 | H41: 36 | I41: 556.23302 | J41: 0.10773833 | K41: 2.8012112
G42: 5 | H42: 45 | I42: 581.52466 | J42: 0.0076638043 | K42: 2.8236075
G43: 6 | H43: 54 | I43: 534.17477 | J43: 0.19497087 | K43: 2.78163
G44: 7 | H44: 63 | I44: 439.73755 | J44: 0.56794797 | K44: 2.6973094
G45: 8 | H45: 72 | I45: 311.69178 | J45: 1.0724639 | K45: 2.5817833
G46: 9 | H46: 81 | I46: 157.92487 | J46: 1.6766397 | K46: 2.4413665
...
